Workbook

Sheet Freddie REMIC Series 2848!!
A1: Zoom | AB1: Months | AC1: Starting balance | AD1: payment | AE1: interest+Servicing | AF1: principal | AG1: remaining balance | AL1: Date | AM1: 1 | AN1: 2 | AO1: 3 | AP1: 4 | AQ1: 6 | AR1: 12 | AS1: 24 | AT1: 36 | AU1: 60 | AV1: 84 | AW1: 120 | AX1: 240 | AY1: 360 | BA1: Weighted Average Life Sensitivity Analysis | CF1: Reformed for report
E2: Traunches | F2: Par Amount | G2: Coupon Rate | H2: WAL Calc | AB2: 1 | AC2: =F11 -> 206500000 | AD2: =PMT($K$4/12,$K$7-AB2+1,-AC2) -> 1428195.9 | AE2: =AC2*$K$4/12 -> 957815.83 | AF2: =AD2-AE2 -> 470380.09 | AG2: =AC2-AF2 -> 2.0602962e+08 | AI2: Traunches | AJ2: WAL | AL2: 39689 | AM2: 0.0163 | AN2: N/A | AO2: 0.0172 | AP2: N/A | AQ2: 0.0197 | AR2: 0.0217 | AS2: 0.0236 | AT2: 0.026 | AU2: 0.031 | AV2: 0.0345 | AW2: 0.0383 | AX2: 0.0447 | AY2: 0.0443 | BA2: PSA Speed | BB2: Tranche CA | BC2: PSA Speed | BD2: Tranche CG | BE2: PSA Speed | BF2: Tranche CM | BG2: PSA Speed | BH2: Tranche CY | BI2: PSA Speed | BJ2: Tranche CZ | BK2: PSA Speed | BL2: Tranche GZ | BM2: PSA Speed | BN2: Tranche TC | BO2: PSA Speed | BP2: Tranche VE | BQ2: PSA Speed | BR2: Collateral | BU2: CA | BV2: CG | BW2: CM | BX2: CY | BY2: CZ | BZ2: GZ | CA2: TC | CB2: VE | CC2: Collateral | CF2: Weighted Average Life Sensitivity Analysis
E3: CA | F3: 32550000 | G3: 0.05 | H3: =F3*G3 -> 1627500 | J3: Assumptions | L3: Asset Principal Amount | AB3: 2 | AC3: =AG2 -> 2.0602962e+08 | AD3: =PMT($K$4/12,$K$7-AB3+1,-AC3) -> 1428195.9 | AE3: =AC3*$K$4/12 -> 955634.05 | AF3: =AD3-AE3 -> 472561.87 | AG3: =AC3-AF3 -> 2.0555706e+08 | AI3: CA | AJ3: =SUM(BE18:BE252)/(12*F3) -> 9.3643558 | BA3: 0 | BB3: =AJ3 -> 9.3643558 | BC3: 0 | BD3: =AJ4 -> 5.8415175 | BE3: 0 | BF3: =AJ5 -> 8.7321876 | BG3: 0 | BH3: =AJ6 -> 18.118717 | BI3: 0 | BJ3: =AJ7 -> 17.912258 | BK3: 0 | BL3: =AJ8 -> 12.530733 | BM3: 0 | BN3: =AJ9 -> 14.958684 | BO3: 0 | BP3: =AJ10 -> 2.2429547 | BQ3: 0 | BR3: =AJ11 -> 11.573998 | BT3: Value | BU3: =SUMPRODUCT(BD$18:BD$252,BF$18:BF$252) -> 32550000 | BV3: =SUMPRODUCT(AR$18:AR$252,AT$18:AT$252) -> 74800000 | BW3: =SUMPRODUCT(AU$18:AU$252,AW$18:AW$252) -> 14000000 | BX3: =SUMPRODUCT(BG$18:BG$252,BI$18:BI$252) -> 13950000 | BY3: =SUMPRODUCT(BL$18:BL$252,BJ$18:BJ$252) -> 24000000 | BZ3: =SUMPRODUCT(AX$18:AX$252,AZ$18:AZ$252) -> 24000000 | CA3: =SUMPRODUCT(BA$18:BA$252,BC$18:BC$252) -> 20000000 | CB3: =SUMPRODUCT(AO$18:AO$252,AQ$18:AQ$252) -> 5200000 | CC3: =SUMPRODUCT(BM$18:BM$252,BO$18:BO$252) -> 2.065e+08 | CF3: PSA Speed | CG3: Tranche CA | CH3: Tranche CG | CI3: Tranche CM | CJ3: Tranche CY | CK3: Tranche CZ | CL3: Tranche GZ | CM3: Tranche TC | CN3: Tranche VE | CO3: Collateral
E4: CG | F4: 74800000 | G4: 0.05 | H4: =F4*G4 -> 3740000 | J4: WAC | K4: =5.566% -> 0.05566 | L4: CA & CY | M4: 0.2251816 | N4: GROUP A | AB4: 3 | AC4: =AG3 -> 2.0555706e+08 | AD4: =PMT($K$4/12,$K$7-AB4+1,-AC4) -> 1428195.9 | AE4: =AC4*$K$4/12 -> 953442.15 | AF4: =AD4-AE4 -> 474753.77 | AG4: =AC4-AF4 -> 2.050823e+08 | AI4: CG | AJ4: =SUM(AS18:AS252)/(12*F4) -> 5.8415175 | AY4: CA | BA4: 100 | BB4: 5.6659899 | BC4: 100 | BD4: 3.5120336 | BE4: 100 | BF4: 6.6123424 | BG4: 100 | BH4: 15.400692 | BI4: 100 | BJ4: 15.711021 | BK4: 100 | BL4: 8.7081094 | BM4: 100 | BN4: 11.202441 | BO4: 100 | BP4: 2.2429547 | BQ4: 100 | BR4: 8.1697338 | BT4: Difference | BU4: =BU3-F3 -> -0.00059144944 | BV4: =BV3-F4 -> 0.00071665645 | BW4: =BW3-F5 -> 0 | BX4: =BX3-F6 -> -0.00018227659 | BY4: =BY3-F7 -> 9.1589987e-05 | BZ4: =BZ3-F7 -> 0.00018005446 | CA4: =CA3-F9 -> 1.937151e-07 | CB4: =CB3-F10 -> 3.8762577e-05 | CC4: =CC3-F11 -> 0 | CF4: 0 | CG4: =BB3 -> 9.3643558 | CH4: =BD3 -> 5.8415175 | CI4: =BF3 -> 8.7321876 | CJ4: =BH3 -> 18.118717 | CK4: =BJ3 -> 17.912258 | CL4: =BL3 -> 12.530733 | CM4: =BN3 -> 14.958684 | CN4: =BP3 -> 2.2429547 | CO4: =BR3 -> 11.573998
E5: CM | F5: 14000000 | G5: 0.05 | H5: =F5*G5 -> 700000 | J5: PSA | K5: 0 | L5: CG, VE, CM, GZ,TC &CZ | M5: 0.7748184 | N5: GROUP B | AB5: 4 | AC5: =AG4 -> 2.050823e+08 | AD5: =PMT($K$4/12,$K$7-AB5+1,-AC5) -> 1428195.9 | AE5: =AC5*$K$4/12 -> 951240.09 | AF5: =AD5-AE5 -> 476955.84 | AG5: =AC5-AF5 -> 2.0460535e+08 | AI5: CM | AJ5: =SUM(AV18:AV252)/(12*F5) -> 8.7321876 | AY5: CG | BA5: 183 | BB5: 4.2294642 | BC5: 183 | BD5: 2.7577516 | BE5: 183 | BF5: 5.2415728 | BG5: 183 | BH5: 12.803596 | BI5: 183 | BJ5: 13.623822 | BK5: 183 | BL5: 6.7645783 | BM5: 183 | BN5: 8.8796982 | BO5: 183 | BP5: 2.2429547 | BQ5: 183 | BR5: 6.3850369 | BT5: X* | BU5: 0.018698323 | BV5: 0.021949747 | BW5: 0.020333588 | BX5: 0.013531563 | BY5: 0.011023044 | BZ5: 0.0089434935 | CA5: 0.015749795 | CB5: 0.025358489 | CC5: 0.016489902 | CF5: 100 | CG5: 5.6659899 | CH5: 3.5120336 | CI5: 6.6123424 | CJ5: 15.400692 | CK5: 15.711021 | CL5: 8.7081094 | CM5: 11.202441 | CN5: 2.2429547 | CO5: 8.1697338
E6: CY | F6: 13950000 | G6: 0.05 | H6: =F6*G6 -> 697500 | J6: CPR | K6: 0.06 | AB6: 5 | AC6: =AG5 -> 2.0460535e+08 | AD6: =PMT($K$4/12,$K$7-AB6+1,-AC6) -> 1428195.9 | AE6: =AC6*$K$4/12 -> 949027.81 | AF6: =AD6-AE6 -> 479168.12 | AG6: =AC6-AF6 -> 2.0412618e+08 | AI6: CY | AJ6: =SUM(BH18:BH252)/(12*F6) -> 18.118717 | AY6: CM | BA6: 300 | BB6: 3.2045167 | BC6: 300 | BD6: 2.2238214 | BE6: 300 | BF6: 4.0695959 | BG6: 300 | BH6: 9.8504401 | BI6: 300 | BJ6: 10.938476 | BK6: 300 | BL6: 5.1646061 | BM6: 300 | BN6: 6.7897131 | BO6: 300 | BP6: 2.1231628 | BQ6: 300 | BR6: 4.781627 | CF6: 183 | CG6: 4.2294642 | CH6: 2.7577516 | CI6: 5.2415728 | CJ6: 12.803596 | CK6: 13.623822 | CL6: 6.7645783 | CM6: 8.8796982 | CN6: 2.2429547 | CO6: 6.3850369
E7: CZ | F7: 24000000 | G7: 0.05 | H7: =F7*G7 -> 1200000 | J7: Term (m) | K7: 240 | AI7: CZ | AJ7: =SUM(BK18:BK252)/(12*AL12) -> 17.912258 | AY7: CY | BA7: 400 | BB7: 2.7191159 | BC7: 400 | BD7: 1.9634823 | BE7: 400 | BF7: 3.472098 | BG7: 400 | BH7: 8.0637162 | BI7: 400 | BJ7: 9.1532973 | BK7: 400 | BL7: 4.3320606 | BM7: 400 | BN7: 5.6467827 | BO7: 400 | BP7: 1.9474084 | BQ7: 400 | BR7: 3.9058293 | CF7: 300 | CG7: 3.2045167 | CH7: 2.2238214 | CI7: 4.0695959 | CJ7: 9.8504401 | CK7: 10.938476 | CL7: 5.1646061 | CM7: 6.7897131 | CN7: 2.1231628 | CO7: 4.781627
E8: GZ | F8: 22000000 | G8: 0.05 | H8: =F8*G8 -> 1100000 | J8: Term to Maturity | K8: 235 | AI8: GZ | AJ8: =SUM(AY18:AY252)/(12*AL11) -> 12.530733 | AY8: CZ | CF8: 400 | CG8: 2.7191159 | CH8: 1.9634823 | CI8: 3.472098 | CJ8: 8.0637162 | CK8: 9.1532973 | CL8: 4.3320606 | CM8: 5.6467827 | CN8: 1.9474084 | CO8: 3.9058293
E9: TC | F9: 20000000 | G9: 0.05 | H9: =F9*G9 -> 1000000 | AI9: TC | AJ9: =SUM(BB18:BB252)/(12*F9) -> 14.958684 | AY9: GZ
E10: VE | F10: 5200000 | G10: 0.05 | H10: =F10*G10 -> 260000 | K10: Assets | AI10: VE | AJ10: =SUM(AP18:AP252)/(12*F10) -> 2.2429547 | AY10: TC | BT10: PSA & X* Sensitivity Analysis
E11: The Assets | F11: =SUM(F3:F10) -> 206500000 | G11: 0.05 | H11: =SUM(H3:H10) -> 10325000 | J11: Balance | K11: 206500000 | AI11: Collateral | AJ11: =SUM(BN18:BN252)/(12*F11) -> 11.573998 | AK11: Max GZ | AL11: =MAX(Y18:Y252) -> 36759331 | AY11: VE | BT11: PSA Speed | BU11: Tranche CA | BV11: Tranche CG | BW11: Tranche CM | BX11: Tranche CY | BY11: Tranche CZ | BZ11: Tranche GZ | CA11: Tranche TC | CB11: Tranche VE | CC11: Collateral
J12: Term | K12: 235 | AK12: Max CZ | AL12: =MAX(AK18:AK252) -> 51365651 | BT12: 0 | BU12: =BU5 -> 0.018698323 | BV12: =BV5 -> 0.021949747 | BW12: =BW5 -> 0.020333588 | BX12: =BX5 -> 0.013531563 | BY12: =BY5 -> 0.011023044 | BZ12: =BZ5 -> 0.0089434935 | CA12: =CA5 -> 0.015749795 | CB12: =CB5 -> 0.025358489 | CC12: =CC5 -> 0.016489902
J13: WACC | K13: 0.05566 | Q13: Principal Check | T13: Principal Check | W13: Principal Check | Z13: Principal Check | AC13: Principal Check | AF13: Principal Check | AI13: Principal Check | AL13: Principal Check | BT13: 100 | BU13: ='PSA 100 vs X'!BU5 -> 0.02192039 | BV13: ='PSA 100 vs X'!BV5 -> 0.024446806 | BW13: ='PSA 100 vs X'!BW5 -> 0.022364026 | BX13: ='PSA 100 vs X'!BX5 -> 0.015325083 | BY13: ='PSA 100 vs X'!BY5 -> 0.013014966 | BZ13: ='PSA 100 vs X'!BZ5 -> 0.0094330705 | CA13: ='PSA 100 vs X'!CA5 -> 0.018586373 | CB13: ='PSA 100 vs X'!CB5 -> 0.025358489 | CC13: ='PSA 100 vs X'!CC5 -> 0.018573832
Q14: =SUM(Q18:Q252) -> 5200000 | T14: =SUM(T18:T252) -> 74800000 | W14: =SUM(W18:W252) -> 14000000 | Z14: =SUM(Z18:Z252) -> 36759331 | AC14: =SUM(AC18:AC252) -> 20000000 | AF14: =SUM(AF18:AF252) -> 32550000 | AI14: =SUM(AI18:AI252) -> 13950000 | AL14: =SUM(AL18:AL252) -> 51168706 | BT14: 183 | BU14: {='PSA 183 on X'!BU5:CC5} -> 0.023516729 | BV14: 0.025345018 | BW14: 0.023591729 | BX14: 0.017086336 | BY14: 0.014918714 | BZ14: 0.00807609 | CA14: 0.020458943 | CB14: 0.025358489 | CC14: 0.020014572
BT15: 300 | BU15: {='PSA 300 vs X'!BU5:CC5} -> 0.02475377 | BV15: 0.025986937 | BW15: 0.024644633 | BX15: 0.019234935 | BY15: 0.017050756 | BZ15: 0.0050007568 | CA15: 0.022223415 | CB15: 0.025575242 | CC15: 0.021548058
N16: Asset Prinicpal Amount | Q16: Tranche VE | T16: Tranche CG | W16: Tranche CM | Z16: Tranche GZ | AC16: Tranche TC | AF16: Tranche CA | AH16: Tranche CY | AK16: Tranche CZ | AN16: Treasury | AP16: Tranche VE | AS16: Tranche CG | AV16: Tranche CM | AY16: Tranche GZ | BB16: Tranche TC | BE16: Tranche CA | BG16: Tranche CY | BJ16: Tranche CZ | BM16: Collateral | BT16: 400 | BU16: {='PSA 400 on X'!BU5:CC5} -> 0.025355313 | BV16: 0.026294327 | BW16: 0.02519042 | BX16: 0.020661746 | BY16: 0.018584184 | BZ16: 0.001909631 | CA16: 0.023220943 | CB16: 0.025850064 | CC16: 0.022559104
A17: CPR Month | B17: Month | C17: Principal | E17: Asset Principal | F17: Payment | G17: Interest+Servicing | H17: Principal | I17: CPR | J17: SMM | K17: Prepayment | L17: Total Collateral CF | M17: Excess CF | N17: Group A | O17: Group B | P17: Balance | Q17: Principal2 | R17: Interest | S17: Balance5 | T17: Principal6 | U17: Interest7 | V17: Balance8 | W17: Principal9 | X17: Interest | Y17: Balance11 | Z17: Principal12 | AA17: Interest(Z) | AB17: Balance14 | AC17: Principal15 | AD17: Interest16 | AE17: Balance20 | AF17: Principal21 | AG17: Interest22 | AH17: Balance202 | AI17: Principal213 | AJ17: Interest224 | AK17: Balance3 | AL17: Principal4 | AM17: Interest(Z) | AN17: Yield Curve | AO17: Cash Flow | AP17: Average life | AQ17: Discount Factor | AR17: Cash Flow | AS17: Average life | AT17: Discount Factor | AU17: Cash Flow | AV17: Average life | AW17: Discount Factor | AX17: Cash Flow | AY17: Average life | AZ17: Discount Factor | BA17: Cash Flow | BB17: Average life | BC17: Discount Factor | BD17: Cash Flow | BE17: Average life | BF17: Discount Factor | BG17: Cash Flow | BH17: Average life | BI17: Discount Factor | BJ17: Cash Flow | BK17: Average life | BL17: Discount Factor | BM17: Cash Flow | BN17: Average life | BO17: Discount Factor
A18: 6 | B18: 1 | C18: =P18+S18+V18+Y18+AB18+AE18+AH18+AK18 -> 206500000 | D18: =C18-E18 -> 0 | E18: =$F$11 -> 206500000 | F18: =PMT($K$13/12,$K$12-B18+1,-E18,0) -> 1444804.7 | G18: =E18*$K$13/12 -> 957815.83 | H18: =F18-G18 -> 486988.84 | I18: =IF(A18<=(30-(240-$K$8)),((A18+(240-$K$7))/30)*$K$6,$K$6)*($K$5/100) -> 0 | J18: =1-(1-I18)^(1/12) -> 0 | K18: =(E18-H18)*J18 -> 0 | L18: =K18+H18+G18 -> 1444804.7 | M18: =L18-G18 -> 486988.84 | N18: =M18*$M$4 -> 109660.92 | O18: =M18*$M$5 -> 377327.91 | P18: =$F$10 -> 5200000 | Q18: =MIN(IF(S18>O18,0,MIN(P18,O18-S18))+IF(P18>0,MIN(AA18,P18)),P18) -> 91666.667 | R18: =P18*($G$10/12) -> 21666.667 | S18: =$F$4 -> 74800000 | T18: =MIN(IF(S18>O18,O18,S18)+IF(S18>0,AM18,0),S18) -> 477327.91 | U18: =S18*($G$4/12) -> 311666.67 | V18: =$F$5 -> 14000000 | W18: =IF(T18+P18<=O18+AM18+AA18,MIN(V18,O18-Q18+AA18-T18+AM18),0) -> 0 | X18: =V18*($G$5/12) -> 58333.333 | Y18: =$F$8 -> 22000000 | Z18: =IF(V18>O18,0,MIN(Y18,O18-V18)) -> 0 | AA18: =Y18*($G$8/12) -> 91666.667 | AB18: =F9 -> 20000000 | AC18: =MIN(IF(Y18>O18,0,MIN(AB18,O18+AM18-Y18))) -> 0 | AD18: =AB18*($G$9/12) -> 83333.333 | AE18: =F3 -> 32550000 | AF18: =IF(AE18>N18,N18,AE18) -> 109660.92 | AG18: =AE18*($G$3/12) -> 135625 | AH18: =F6 -> 13950000 | AI18: =IF(AE18>N18,0,MIN(AH18,N18-AE18)) -> 0 | AJ18: =AH18*($G$6/12) -> 58125 | AK18: =F7 -> 24000000 | AL18: =IF(AB18>0,IF(AB18>O18,0,MIN(AK18,O18-AB18)),O18) -> 0 | AM18: =AK18*($G$7/12) -> 100000 | AN18: =FORECAST(B18, $AM$2:$AY$2,$AM$1:$AY$1) -> 0.022010844 | AO18: =Q18+R18 -> 113333.33 | AP18: =Q18*B18 -> 91666.667 | AQ18: =1/(1+(AN18+$CB$5)/12)^$B18 -> 0.99606808 | AR18: =T18+U18 -> 788994.58 | AS18: =T18*A18 -> 2863967.5 | AT18: =1/(1+(AN18+$BV$5)/12)^$B18 -> 0.99634999 | AU18: =W18+X18 -> 58333.333 | AV18: =W18*A18 -> 0 | AW18: =1/(1+(AN18+$BW$5)/12)^$B18 -> 0.99648371 | AX18: =IF(Y19>Y18,0,Z18+AA18) -> 0 | AY18: =A18*Z18 -> 0 | AZ18: =1/(1+(AN18+$BZ$5)/12)^$B18 -> 0.99742711 | BA18: =AC18+AD18 -> 83333.333 | BB18: =AC18*A18 -> 0 | BC18: =1/(1+(AN18+$CA$5)/12)^$B18 -> 0.99686315 | BD18: =AF18+AG18 -> 245285.92 | BE18: =AF18*A18 -> 657965.55 | BF18: =1/(1+(AN18+$BU$5)/12)^$B18 -> 0.99661904 | BG18: =AI18+AJ18 -> 58125 | BH18: =AI18*A18 -> 0 | BI18: =1/(1+(AN18+$BX$5)/12)^$B18 -> 0.99704688 | BJ18: =IF(AK19>AK18,0,AL18+AM18) -> 0 | BK18: =A18*AL18 -> 0 | BL18: =1/(1+(AN18+$BY$5)/12)^$B18 -> 0.99725473 | BM18: =AO18+AR18+AU18+AX18+BA18+BD18+BG18+BJ18 -> 1347405.5 | BN18: =M18*B18 -> 486988.84 | BO18: =1/(1+(AN18+$CC$5)/12)^$B18 -> 0.99680187
A19: 7 | B19: 2 | C19: =P19+S19+V19+Y19+AB19+AE19+AH19+AK19 -> 2.0601301e+08 | D19: =C19-E19 -> 0 | E19: =E18-H18-K18 -> 2.0601301e+08 | F19: =PMT($K$13/12,$K$12-B19+1,-E19,0) -> 1444804.7 | G19: =E19*$K$13/12 -> 955557.02 | H19: =F19-G19 -> 489247.66 | I19: =IF(A19<=(30-(240-$K$8)),((A19+(240-$K$7))/30)*$K$6,$K$6)*($K$5/100) -> 0 | J19: =1-(1-I19)^(1/12) -> 0 | K19: =(E19-H19)*J19 -> 0 | L19: =K19+H19+G19 -> 1444804.7 | M19: =L19-G19 -> 489247.66 | N19: =M19*$M$4 -> 110169.57 | O19: =M19*$M$5 -> 379078.09 | P19: =P18-Q18 -> 5108333.3 | Q19: =MIN(IF(S19>O19,0,MIN(P19,O19-S19))+IF(P19>0,MIN(AA19,P19)),P19) -> 92048.611 | R19: =P19*($G$10/12) -> 21284.722 | S19: =S18-T18 -> 74322672 | T19: =MIN(IF(S19>O19,O19,S19)+IF(S19>0,AM19,0),S19) -> 479494.75 | U19: =S19*($G$4/12) -> 309677.8 | V19: =V18-W18 -> 14000000 | W19: =IF(T19+P19<=O19+AM19+AA19,MIN(V19,O19-Q19+AA19-T19+AM19),0) -> 0 | X19: =V19*($G$5/12) -> 58333.333 | Y19: =IF(V18>O18,(IF(V18>AA18+O18+AM18,Y18+AA18,Y18+AA18-((AA18+O18+AM18)-V18))),Y18-Z18) -> 22091667 | Z19: =MIN(IF(V19>O19,0,MIN(Y19,O19-V19))+IF(AM18>V18,AM18,0),Y19) -> 0 | AA19: =Y19*($G$8/12) -> 92048.611 | AB19: =AB18-AC18 -> 20000000 | AC19: =MIN(IF(Y19>O19,0,MIN(AB19,O19+AM19-Y19))) -> 0 | AD19: =AB19*($G$9/12) -> 83333.333 | AE19: =AE18-AF18 -> 32440339 | AF19: =IF(AE19>N19,N19,AE19) -> 110169.57 | AG19: =AE19*($G$3/12) -> 135168.08 | AH19: =AH18-AI18 -> 13950000 | AI19: =IF(AE19>N19,0,MIN(AH19,N19-AE19)) -> 0 | AJ19: =AH19*($G$6/12) -> 58125 | AK19: =IF(AL18=0,AK18+AM18,AK18-AL18) -> 24100000 | AL19: =MIN(IF(AB19>0,IF(AB19>O19,0,MIN(AK19,O19-AB19)),O19),AK19) -> 0 | AM19: =AK19*($G$7/12) -> 100416.67 | AN19: =FORECAST(B19, $AM$2:$AY$2,$AM$1:$AY$1) -> 0.022091251 | AO19: =Q19+R19 -> 113333.33 | AP19: =Q19*B19 -> 184097.22 | AQ19: =1/(1+(AN19+$CB$5)/12)^$B19 -> 0.99213837 | AR19: =T19+U19 -> 789172.55 | AS19: =T19*A19 -> 3356463.3 | AT19: =1/(1+(AN19+$BV$5)/12)^$B19 -> 0.99270005 | AU19: =W19+X19 -> 58333.333 | AV19: =W19*A19 -> 0 | AW19: =1/(1+(AN19+$BW$5)/12)^$B19 -> 0.99296651 | AX19: =IF(Y20>Y19,0,Z19+AA19) -> 0 | AY19: =A19*Z19 -> 0 | AZ19: =1/(1+(AN19+$BZ$5)/12)^$B19 -> 0.99484754 | BA19: =AC19+AD19 -> 83333.333 | BB19: =AC19*A19 -> 0 | BC19: =1/(1+(AN19+$CA$5)/12)^$B19 -> 0.99372287 | BD19: =AF19+AG19 -> 245337.65 | BE19: =AF19*A19 -> 771186.98 | BF19: =1/(1+(AN19+$BU$5)/12)^$B19 -> 0.99323624 | BG19: =AI19+AJ19 -> 58125 | BH19: =AI19*A19 -> 0 | BI19: =1/(1+(AN19+$BX$5)/12)^$B19 -> 0.9940892 | BJ19: =IF(AK20>AK19,0,AL19+AM19) -> 0 | BK19: =A19*AL19 -> 0 | BL19: =1/(1+(AN19+$BY$5)/12)^$B19 -> 0.99450371 | BM19: =AO19+AR19+AU19+AX19+BA19+BD19+BG19+BJ19 -> 1347635.2 | BN19: =M19*B19 -> 978495.31 | BO19: =1/(1+(AN19+$CC$5)/12)^$B19 -> 0.99360069 | BT19: Changes in Yield Curve and X* Sensitivity Analysis (assuming 183 PSA)
A20: 8 | B20: 3 | C20: =P20+S20+V20+Y20+AB20+AE20+AH20+AK20 -> 2.0552376e+08 | D20: =C20-E20 -> 0 | E20: =E19-H19-K19 -> 2.0552376e+08 | F20: =PMT($K$13/12,$K$12-B20+1,-E20,0) -> 1444804.7 | G20: =E20*$K$13/12 -> 953287.72 | H20: =F20-G20 -> 491516.95 | I20: =IF(A20<=(30-(240-$K$8)),((A20+(240-$K$7))/30)*$K$6,$K$6)*($K$5/100) -> 0 | J20: =1-(1-I20)^(1/12) -> 0 | K20: =(E20-H20)*J20 -> 0 | L20: =K20+H20+G20 -> 1444804.7 | M20: =L20-G20 -> 491516.95 | N20: =M20*$M$4 -> 110680.57 | O20: =M20*$M$5 -> 380836.38 | P20: =P19-Q19 -> 5016284.7 | Q20: =MIN(IF(S20>O20,0,MIN(P20,O20-S20))+IF(P20>0,MIN(AA20,P20)),P20) -> 92432.147 | R20: =P20*($G$10/12) -> 20901.186 | S20: =S19-T19 -> 73843177 | T20: =MIN(IF(S20>O20,O20,S20)+IF(S20>0,AM20,0),S20) -> 481671.45 | U20: =S20*($G$4/12) -> 307679.91 | V20: =V19-W19 -> 14000000 | W20: =IF(T20+P20<=O20+AM20+AA20,MIN(V20,O20-Q20+AA20-T20+AM20),0) -> 0 | X20: =V20*($G$5/12) -> 58333.333 | Y20: =IF(V19>O19,(IF(V19>AA19+O19+AM19,Y19+AA19,Y19+AA19-((AA19+O19+AM19)-V19))),Y19-Z19) -> 22183715 | Z20: =MIN(IF(V20>O20,0,MIN(Y20,O20-V20))+IF(AM19>V19,AM19,0),Y20) -> 0 | AA20: =Y20*($G$8/12) -> 92432.147 | AB20: =AB19-AC19 -> 20000000 | AC20: =MIN(IF(Y20>O20,0,MIN(AB20,O20+AM20-Y20))) -> 0 | AD20: =AB20*($G$9/12) -> 83333.333 | AE20: =AE19-AF19 -> 32330170 | AF20: =IF(AE20>N20,N20,AE20) -> 110680.57 | AG20: =AE20*($G$3/12) -> 134709.04 | AH20: =AH19-AI19 -> 13950000 | AI20: =IF(AE20>N20,0,MIN(AH20,N20-AE20)) -> 0 | AJ20: =AH20*($G$6/12) -> 58125 | AK20: =IF(AL19=0,AK19+AM19,AK19-AL19) -> 24200417 | AL20: =MIN(IF(AB20>0,IF(AB20>O20,0,MIN(AK20,O20-AB20)),O20),AK20) -> 0 | AM20: =AK20*($G$7/12) -> 100835.07 | AN20: =FORECAST(B20, $AM$2:$AY$2,$AM$1:$AY$1) -> 0.022171658 | AO20: =Q20+R20 -> 113333.33 | AP20: =Q20*B20 -> 277296.44 | AQ20: =1/(1+(AN20+$CB$5)/12)^$B20 -> 0.98821098 | AR20: =T20+U20 -> 789351.35 | AS20: =T20*A20 -> 3853371.6 | AT20: =1/(1+(AN20+$BV$5)/12)^$B20 -> 0.98905027 | AU20: =W20+X20 -> 58333.333 | AV20: =W20*A20 -> 0 | AW20: =1/(1+(AN20+$BW$5)/12)^$B20 -> 0.98944853 | AX20: =IF(Y21>Y20,0,Z20+AA20) -> 0 | AY20: =A20*Z20 -> 0 | AZ20: =1/(1+(AN20+$BZ$5)/12)^$B20 -> 0.99226138 | BA20: =AC20+AD20 -> 83333.333 | BB20: =AC20*A20 -> 0 | BC20: =1/(1+(AN20+$CA$5)/12)^$B20 -> 0.99057924 | BD20: =AF20+AG20 -> 245389.61 | BE20: =AF20*A20 -> 885444.58 | BF20: =1/(1+(AN20+$BU$5)/12)^$B20 -> 0.98985171 | BG20: =AI20+AJ20 -> 58125 | BH20: =AI20*A20 -> 0 | BI20: =1/(1+(AN20+$BX$5)/12)^$B20 -> 0.99112705 | BJ20: =IF(AK21>AK20,0,AL20+AM20) -> 0 | BK20: =A20*AL20 -> 0 | BL20: =1/(1+(AN20+$BY$5)/12)^$B20 -> 0.99174703 | BM20: =AO20+AR20+AU20+AX20+BA20+BD20+BG20+BJ20 -> 1347866 | BN20: =M20*B20 -> 1474550.8 | BO20: =1/(1+(AN20+$CC$5)/12)^$B20 -> 0.99039656 | BU20: Tranche CA | BV20: Tranche CG | BW20: Tranche CM | BX20: Tranche CY | BY20: Tranche CZ | BZ20: Tranche GZ | CA20: Tranche TC | CB20: Tranche VE | CC20: Collateral
A21: 9 | B21: 4 | C21: =P21+S21+V21+Y21+AB21+AE21+AH21+AK21 -> 2.0503225e+08 | D21: =C21-E21 -> 0 | E21: =E20-H20-K20 -> 2.0503225e+08 | F21: =PMT($K$13/12,$K$12-B21+1,-E21,0) -> 1444804.7 | G21: =E21*$K$13/12 -> 951007.9 | H21: =F21-G21 -> 493796.77 | I21: =IF(A21<=(30-(240-$K$8)),((A21+(240-$K$7))/30)*$K$6,$K$6)*($K$5/100) -> 0 | J21: =1-(1-I21)^(1/12) -> 0 | K21: =(E21-H21)*J21 -> 0 | L21: =K21+H21+G21 -> 1444804.7 | M21: =L21-G21 -> 493796.77 | N21: =M21*$M$4 -> 111193.95 | O21: =M21*$M$5 -> 382602.82 | P21: =P20-Q20 -> 4923852.6 | Q21: =MIN(IF(S21>O21,0,MIN(P21,O21-S21))+IF(P21>0,MIN(AA21,P21)),P21) -> 92817.281 | R21: =P21*($G$10/12) -> 20516.052 | S21: =S20-T20 -> 73361506 | T21: =MIN(IF(S21>O21,O21,S21)+IF(S21>0,AM21,0),S21) -> 483858.04 | U21: =S21*($G$4/12) -> 305672.94 | V21: =V20-W20 -> 14000000 | W21: =IF(T21+P21<=O21+AM21+AA21,MIN(V21,O21-Q21+AA21-T21+AM21),0) -> 0 | X21: =V21*($G$5/12) -> 58333.333 | Y21: =IF(V20>O20,(IF(V20>AA20+O20+AM20,Y20+AA20,Y20+AA20-((AA20+O20+AM20)-V20))),Y20-Z20) -> 22276147 | Z21: =MIN(IF(V21>O21,0,MIN(Y21,O21-V21))+IF(AM20>V20,AM20,0),Y21) -> 0 | AA21: =Y21*($G$8/12) -> 92817.281 | AB21: =AB20-AC20 -> 20000000 | AC21: =MIN(IF(Y21>O21,0,MIN(AB21,O21+AM21-Y21))) -> 0 | AD21: =AB21*($G$9/12) -> 83333.333 | AE21: =AE20-AF20 -> 32219489 | AF21: =IF(AE21>N21,N21,AE21) -> 111193.95 | AG21: =AE21*($G$3/12) -> 134247.87 | AH21: =AH20-AI20 -> 13950000 | AI21: =IF(AE21>N21,0,MIN(AH21,N21-AE21)) -> 0 | AJ21: =AH21*($G$6/12) -> 58125 | AK21: =IF(AL20=0,AK20+AM20,AK20-AL20) -> 24301252 | AL21: =MIN(IF(AB21>0,IF(AB21>O21,0,MIN(AK21,O21-AB21)),O21),AK21) -> 0 | AM21: =AK21*($G$7/12) -> 101255.22 | AN21: =FORECAST(B21, $AM$2:$AY$2,$AM$1:$AY$1) -> 0.022252065 | AO21: =Q21+R21 -> 113333.33 | AP21: =Q21*B21 -> 371269.12 | AQ21: =1/(1+(AN21+$CB$5)/12)^$B21 -> 0.98428599 | AR21: =T21+U21 -> 789530.98 | AS21: =T21*A21 -> 4354722.3 | AT21: =1/(1+(AN21+$BV$5)/12)^$B21 -> 0.98540075 | AU21: =W21+X21 -> 58333.333 | AV21: =W21*A21 -> 0 | AW21: =1/(1+(AN21+$BW$5)/12)^$B21 -> 0.98592983 | AX21: =IF(Y22>Y21,0,Z21+AA21) -> 0 | AY21: =A21*Z21 -> 0 | AZ21: =1/(1+(AN21+$BZ$5)/12)^$B21 -> 0.98966871 | BA21: =AC21+AD21 -> 83333.333 | BB21: =AC21*A21 -> 0 | BC21: =1/(1+(AN21+$CA$5)/12)^$B21 -> 0.98743237 | BD21: =AF21+AG21 -> 245441.82 | BE21: =AF21*A21 -> 1000745.5 | BF21: =1/(1+(AN21+$BU$5)/12)^$B21 -> 0.98646553 | BG21: =AI21+AJ21 -> 58125 | BH21: =AI21*A21 -> 0 | BI21: =1/(1+(AN21+$BX$5)/12)^$B21 -> 0.98816052 | BJ21: =IF(AK22>AK21,0,AL21+AM21) -> 0 | BK21: =A21*AL21 -> 0 | BL21: =1/(1+(AN21+$BY$5)/12)^$B21 -> 0.98898476 | BM21: =AO21+AR21+AU21+AX21+BA21+BD21+BG21+BJ21 -> 1348097.8 | BN21: =M21*B21 -> 1975187.1 | BO21: =1/(1+(AN21+$CC$5)/12)^$B21 -> 0.98718957 | BT21: Original Yield Curve (Normal) | BU21: =BU14 -> 0.023516729 | BV21: =BV14 -> 0.025345018 | BW21: =BW14 -> 0.023591729 | BX21: =BX14 -> 0.017086336 | BY21: =BY14 -> 0.014918714 | BZ21: =BZ14 -> 0.00807609 | CA21: =CA14 -> 0.020458943 | CB21: =CB14 -> 0.025358489 | CC21: =CC14 -> 0.020014572
A22: 10 | B22: 5 | C22: =P22+S22+V22+Y22+AB22+AE22+AH22+AK22 -> 2.0453845e+08 | D22: =C22-E22 -> 0 | E22: =E21-H21-K21 -> 2.0453845e+08 | F22: =PMT($K$13/12,$K$12-B22+1,-E22,0) -> 1444804.7 | G22: =E22*$K$13/12 -> 948717.51 | H22: =F22-G22 -> 496087.16 | I22: =IF(A22<=(30-(240-$K$8)),((A22+(240-$K$7))/30)*$K$6,$K$6)*($K$5/100) -> 0 | J22: =1-(1-I22)^(1/12) -> 0 | K22: =(E22-H22)*J22 -> 0 | L22: =K22+H22+G22 -> 1444804.7 | M22: =L22-G22 -> 496087.16 | N22: =M22*$M$4 -> 111709.7 | O22: =M22*$M$5 -> 384377.46 | P22: =P21-Q21 -> 4831035.3 | Q22: =MIN(IF(S22>O22,0,MIN(P22,O22-S22))+IF(P22>0,MIN(AA22,P22)),P22) -> 93204.02 | R22: =P22*($G$10/12) -> 20129.314 | S22: =S21-T21 -> 72877648 | T22: =MIN(IF(S22>O22,O22,S22)+IF(S22>0,AM22,0),S22) -> 486054.57 | U22: =S22*($G$4/12) -> 303656.87 | V22: =V21-W21 -> 14000000 | W22: =IF(T22+P22<=O22+AM22+AA22,MIN(V22,O22-Q22+AA22-T22+AM22),0) -> 0 | X22: =V22*($G$5/12) -> 58333.333 | Y22: =IF(V21>O21,(IF(V21>AA21+O21+AM21,Y21+AA21,Y21+AA21-((AA21+O21+AM21)-V21))),Y21-Z21) -> 22368965 | Z22: =MIN(IF(V22>O22,0,MIN(Y22,O22-V22))+IF(AM21>V21,AM21,0),Y22) -> 0 | AA22: =Y22*($G$8/12) -> 93204.02 | AB22: =AB21-AC21 -> 20000000 | AC22: =MIN(IF(Y22>O22,0,MIN(AB22,O22+AM22-Y22))) -> 0 | AD22: =AB22*($G$9/12) -> 83333.333 | AE22: =AE21-AF21 -> 32108295 | AF22: =IF(AE22>N22,N22,AE22) -> 111709.7 | AG22: =AE22*($G$3/12) -> 133784.56 | AH22: =AH21-AI21 -> 13950000 | AI22: =IF(AE22>N22,0,MIN(AH22,N22-AE22)) -> 0 | AJ22: =AH22*($G$6/12) -> 58125 | AK22: =IF(AL21=0,AK21+AM21,AK21-AL21) -> 24402507 | AL22: =MIN(IF(AB22>0,IF(AB22>O22,0,MIN(AK22,O22-AB22)),O22),AK22) -> 0 | AM22: =AK22*($G$7/12) -> 101677.11 | AN22: =FORECAST(B22, $AM$2:$AY$2,$AM$1:$AY$1) -> 0.022332473 | AO22: =Q22+R22 -> 113333.33 | AP22: =Q22*B22 -> 466020.1 | AQ22: =1/(1+(AN22+$CB$5)/12)^$B22 -> 0.98036351 | AR22: =T22+U22 -> 789711.44 | AS22: =T22*A22 -> 4860545.7 | AT22: =1/(1+(AN22+$BV$5)/12)^$B22 -> 0.98175159 | AU22: =W22+X22 -> 58333.333 | AV22: =W22*A22 -> 0 | AW22: =1/(1+(AN22+$BW$5)/12)^$B22 -> 0.98241054 | AX22: =IF(Y23>Y22,0,Z22+AA22) -> 0 | AY22: =A22*Z22 -> 0 | AZ22: =1/(1+(AN22+$BZ$5)/12)^$B22 -> 0.98706963 | BA22: =AC22+AD22 -> 83333.333 | BB22: =AC22*A22 -> 0 | BC22: =1/(1+(AN22+$CA$5)/12)^$B22 -> 0.98428235 | BD22: =AF22+AG22 -> 245494.26 | BE22: =AF22*A22 -> 1117097 | BF22: =1/(1+(AN22+$BU$5)/12)^$B22 -> 0.98307781 | BG22: =AI22+AJ22 -> 58125 | BH22: =AI22*A22 -> 0 | BI22: =1/(1+(AN22+$BX$5)/12)^$B22 -> 0.98518971 | BJ22: =IF(AK23>AK22,0,AL22+AM22) -> 0 | BK22: =A22*AL22 -> 0 | BL22: =1/(1+(AN22+$BY$5)/12)^$B22 -> 0.98621702 | BM22: =AO22+AR22+AU22+AX22+BA22+BD22+BG22+BJ22 -> 1348330.7 | BN22: =M22*B22 -> 2480435.8 | BO22: =1/(1+(AN22+$CC$5)/12)^$B22 -> 0.98397983 | BT22: Inverse Yield Curve | BU22: ='Inverse Yield Curve'!BU5 -> 0.018578899 | BV22: ='Inverse Yield Curve'!BV5 -> 0.018946407 | BW22: ='Inverse Yield Curve'!BW5 -> 0.018595214 | BX22: ='Inverse Yield Curve'!BX5 -> 0.017279956 | BY22: ='Inverse Yield Curve'!BY5 -> 0.016580002 | BZ22: ='Inverse Yield Curve'!BZ5 -> 0.0044188321 | CA22: ='Inverse Yield Curve'!CA5 -> 0.017966763 | CB22: ='Inverse Yield Curve'!CB5 -> 0.018949117 | CC22: ='Inverse Yield Curve'!CC5 -> 0.017784164
A23: 11 | B23: 6 | C23: =P23+S23+V23+Y23+AB23+AE23+AH23+AK23 -> 2.0404236e+08 | D23: =C23-E23 -> 0 | E23: =E22-H22-K22 -> 2.0404236e+08 | F23: =PMT($K$13/12,$K$12-B23+1,-E23,0) -> 1444804.7 | G23: =E23*$K$13/12 -> 946416.49 | H23: =F23-G23 -> 498388.18 | I23: =IF(A23<=(30-(240-$K$8)),((A23+(240-$K$7))/30)*$K$6,$K$6)*($K$5/100) -> 0 | J23: =1-(1-I23)^(1/12) -> 0 | K23: =(E23-H23)*J23 -> 0 | L23: =K23+H23+G23 -> 1444804.7 | M23: =L23-G23 -> 498388.18 | N23: =M23*$M$4 -> 112227.85 | O23: =M23*$M$5 -> 386160.33 | P23: =P22-Q22 -> 4737831.3 | Q23: =MIN(IF(S23>O23,0,MIN(P23,O23-S23))+IF(P23>0,MIN(AA23,P23)),P23) -> 93592.37 | R23: =P23*($G$10/12) -> 19740.964 | S23: =S22-T22 -> 72391593 | T23: =MIN(IF(S23>O23,O23,S23)+IF(S23>0,AM23,0),S23) -> 488261.1 | U23: =S23*($G$4/12) -> 301631.64 | V23: =V22-W22 -> 14000000 | W23: =IF(T23+P23<=O23+AM23+AA23,MIN(V23,O23-Q23+AA23-T23+AM23),0) -> 0 | X23: =V23*($G$5/12) -> 58333.333 | Y23: =IF(V22>O22,(IF(V22>AA22+O22+AM22,Y22+AA22,Y22+AA22-((AA22+O22+AM22)-V22))),Y22-Z22) -> 22462169 | Z23: =MIN(IF(V23>O23,0,MIN(Y23,O23-V23))+IF(AM22>V22,AM22,0),Y23) -> 0 | AA23: =Y23*($G$8/12) -> 93592.37 | AB23: =AB22-AC22 -> 20000000 | AC23: =MIN(IF(Y23>O23,0,MIN(AB23,O23+AM23-Y23))) -> 0 | AD23: =AB23*($G$9/12) -> 83333.333 | AE23: =AE22-AF22 -> 31996585 | AF23: =IF(AE23>N23,N23,AE23) -> 112227.85 | AG23: =AE23*($G$3/12) -> 133319.11 | AH23: =AH22-AI22 -> 13950000 | AI23: =IF(AE23>N23,0,MIN(AH23,N23-AE23)) -> 0 | AJ23: =AH23*($G$6/12) -> 58125 | AK23: =IF(AL22=0,AK22+AM22,AK22-AL22) -> 24504184 | AL23: =MIN(IF(AB23>0,IF(AB23>O23,0,MIN(AK23,O23-AB23)),O23),AK23) -> 0 | AM23: =AK23*($G$7/12) -> 102100.77 | AN23: =FORECAST(B23, $AM$2:$AY$2,$AM$1:$AY$1) -> 0.02241288 | AO23: =Q23+R23 -> 113333.33 | AP23: =Q23*B23 -> 561554.22 | AQ23: =1/(1+(AN23+$CB$5)/12)^$B23 -> 0.97644362 | AR23: =T23+U23 -> 789892.74 | AS23: =T23*A23 -> 5370872.1 | AT23: =1/(1+(AN23+$BV$5)/12)^$B23 -> 0.97810289 | AU23: =W23+X23 -> 58333.333 | AV23: =W23*A23 -> 0 | AW23: =1/(1+(AN23+$BW$5)/12)^$B23 -> 0.97889073 | AX23: =IF(Y24>Y23,0,Z23+AA23) -> 0 | AY23: =A23*Z23 -> 0 | AZ23: =1/(1+(AN23+$BZ$5)/12)^$B23 -> 0.98446421 | BA23: =AC23+AD23 -> 83333.333 | BB23: =AC23*A23 -> 0 | BC23: =1/(1+(AN23+$CA$5)/12)^$B23 -> 0.98112926 | BD23: =AF23+AG23 -> 245546.95 | BE23: =AF23*A23 -> 1234506.3 | BF23: =1/(1+(AN23+$BU$5)/12)^$B23 -> 0.97968864 | BG23: =AI23+AJ23 -> 58125 | BH23: =AI23*A23 -> 0 | BI23: =1/(1+(AN23+$BX$5)/12)^$B23 -> 0.9822147 | BJ23: =IF(AK24>AK23,0,AL23+AM23) -> 0 | BK23: =A23*AL23 -> 0 | BL23: =1/(1+(AN23+$BY$5)/12)^$B23 -> 0.98344387 | BM23: =AO23+AR23+AU23+AX23+BA23+BD23+BG23+BJ23 -> 1348564.7 | BN23: =M23*B23 -> 2990329.1 | BO23: =1/(1+(AN23+$CC$5)/12)^$B23 -> 0.98076742 | BT23: Flatter Yield Curve | BU23: ='Flatter Yield Curve'!BU5 -> 0.024528739 | BV23: ='Flatter Yield Curve'!BV5 -> 0.025417296 | BW23: ='Flatter Yield Curve'!BW5 -> 0.02456712 | BX23: ='Flatter Yield Curve'!BX5 -> 0.021393673 | BY23: ='Flatter Yield Curve'!BY5 -> 0.02017482 | BZ23: ='Flatter Yield Curve'!BZ5 -> 0.0099139265 | CA23: ='Flatter Yield Curve'!CA5 -> 0.023046558 | CB23: ='Flatter Yield Curve'!CB5 -> 0.025423847 | CC23: ='Flatter Yield Curve'!CC5 -> 0.022756985
A24: 12 | B24: 7 | C24: =P24+S24+V24+Y24+AB24+AE24+AH24+AK24 -> 2.0354397e+08 | D24: =C24-E24 -> 0 | E24: =E23-H23-K23 -> 2.0354397e+08 | F24: =PMT($K$13/12,$K$12-B24+1,-E24,0) -> 1444804.7 | G24: =E24*$K$13/12 -> 944104.8 | H24: =F24-G24 -> 500699.87 | I24: =IF(A24<=(30-(240-$K$8)),((A24+(240-$K$7))/30)*$K$6,$K$6)*($K$5/100) -> 0 | J24: =1-(1-I24)^(1/12) -> 0 | K24: =(E24-H24)*J24 -> 0 | L24: =K24+H24+G24 -> 1444804.7 | M24: =L24-G24 -> 500699.87 | N24: =M24*$M$4 -> 112748.4 | O24: =M24*$M$5 -> 387951.47 | P24: =P23-Q23 -> 4644238.9 | Q24: =MIN(IF(S24>O24,0,MIN(P24,O24-S24))+IF(P24>0,MIN(AA24,P24)),P24) -> 93982.338 | R24: =P24*($G$10/12) -> 19350.995 | S24: =S23-T23 -> 71903332 | T24: =MIN(IF(S24>O24,O24,S24)+IF(S24>0,AM24,0),S24) -> 490477.66 | U24: =S24*($G$4/12) -> 299597.22 | V24: =V23-W23 -> 14000000 | W24: =IF(T24+P24<=O24+AM24+AA24,MIN(V24,O24-Q24+AA24-T24+AM24),0) -> 0 | X24: =V24*($G$5/12) -> 58333.333 | Y24: =IF(V23>O23,(IF(V23>AA23+O23+AM23,Y23+AA23,Y23+AA23-((AA23+O23+AM23)-V23))),Y23-Z23) -> 22555761 | Z24: =MIN(IF(V24>O24,0,MIN(Y24,O24-V24))+IF(AM23>V23,AM23,0),Y24) -> 0 | AA24: =Y24*($G$8/12) -> 93982.338 | AB24: =AB23-AC23 -> 20000000 | AC24: =MIN(IF(Y24>O24,0,MIN(AB24,O24+AM24-Y24))) -> 0 | AD24: =AB24*($G$9/12) -> 83333.333 | AE24: =AE23-AF23 -> 31884357 | AF24: =IF(AE24>N24,N24,AE24) -> 112748.4 | AG24: =AE24*($G$3/12) -> 132851.49 | AH24: =AH23-AI23 -> 13950000 | AI24: =IF(AE24>N24,0,MIN(AH24,N24-AE24)) -> 0 | AJ24: =AH24*($G$6/12) -> 58125 | AK24: =IF(AL23=0,AK23+AM23,AK23-AL23) -> 24606285 | AL24: =MIN(IF(AB24>0,IF(AB24>O24,0,MIN(AK24,O24-AB24)),O24),AK24) -> 0 | AM24: =AK24*($G$7/12) -> 102526.19 | AN24: =FORECAST(B24, $AM$2:$AY$2,$AM$1:$AY$1) -> 0.022493287 | AO24: =Q24+R24 -> 113333.33 | AP24: =Q24*B24 -> 657876.37 | AQ24: =1/(1+(AN24+$CB$5)/12)^$B24 -> 0.97252643 | AR24: =T24+U24 -> 790074.88 | AS24: =T24*A24 -> 5885731.9 | AT24: =1/(1+(AN24+$BV$5)/12)^$B24 -> 0.97445473 | AU24: =W24+X24 -> 58333.333 | AV24: =W24*A24 -> 0 | AW24: =1/(1+(AN24+$BW$5)/12)^$B24 -> 0.97537051 | AX24: =IF(Y25>Y24,0,Z24+AA24) -> 0 | AY24: =A24*Z24 -> 0 | AZ24: =1/(1+(AN24+$BZ$5)/12)^$B24 -> 0.98185254 | BA24: =AC24+AD24 -> 83333.333 | BB24: =AC24*A24 -> 0 | BC24: =1/(1+(AN24+$CA$5)/12)^$B24 -> 0.97797322 | BD24: =AF24+AG24 -> 245599.89 | BE24: =AF24*A24 -> 1352980.8 | BF24: =1/(1+(AN24+$BU$5)/12)^$B24 -> 0.97629812 | BG24: =AI24+AJ24 -> 58125 | BH24: =AI24*A24 -> 0 | BI24: =1/(1+(AN24+$BX$5)/12)^$B24 -> 0.9792356 | BJ24: =IF(AK25>AK24,0,AL24+AM24) -> 0 | BK24: =A24*AL24 -> 0 | BL24: =1/(1+(AN24+$BY$5)/12)^$B24 -> 0.98066542 | BM24: =AO24+AR24+AU24+AX24+BA24+BD24+BG24+BJ24 -> 1348799.8 | BN24: =M24*B24 -> 3504899.1 | BO24: =1/(1+(AN24+$CC$5)/12)^$B24 -> 0.97755244
A25: 13 | B25: 8 | C25: =P25+S25+V25+Y25+AB25+AE25+AH25+AK25 -> 2.0304327e+08 | D25: =C25-E25 -> 0 | E25: =E24-H24-K24 -> 2.0304327e+08 | F25: =PMT($K$13/12,$K$12-B25+1,-E25,0) -> 1444804.7 | G25: =E25*$K$13/12 -> 941782.39 | H25: =F25-G25 -> 503022.28 | I25: =IF(A25<=(30-(240-$K$8)),((A25+(240-$K$7))/30)*$K$6,$K$6)*($K$5/100) -> 0 | J25: =1-(1-I25)^(1/12) -> 0 | K25: =(E25-H25)*J25 -> 0 | L25: =K25+H25+G25 -> 1444804.7 | M25: =L25-G25 -> 503022.28 | N25: =M25*$M$4 -> 113271.36 | O25: =M25*$M$5 -> 389750.92 | P25: =P24-Q24 -> 4550256.6 | Q25: =MIN(IF(S25>O25,0,MIN(P25,O25-S25))+IF(P25>0,MIN(AA25,P25)),P25) -> 94373.931 | R25: =P25*($G$10/12) -> 18959.402 | S25: =S24-T24 -> 71412855 | T25: =MIN(IF(S25>O25,O25,S25)+IF(S25>0,AM25,0),S25) -> 492704.3 | U25: =S25*($G$4/12) -> 297553.56 | V25: =V24-W24 -> 14000000 | W25: =IF(T25+P25<=O25+AM25+AA25,MIN(V25,O25-Q25+AA25-T25+AM25),0) -> 0 | X25: =V25*($G$5/12) -> 58333.333 | Y25: =IF(V24>O24,(IF(V24>AA24+O24+AM24,Y24+AA24,Y24+AA24-((AA24+O24+AM24)-V24))),Y24-Z24) -> 22649743 | Z25: =MIN(IF(V25>O25,0,MIN(Y25,O25-V25))+IF(AM24>V24,AM24,0),Y25) -> 0 | AA25: =Y25*($G$8/12) -> 94373.931 | AB25: =AB24-AC24 -> 20000000 | AC25: =MIN(IF(Y25>O25,0,MIN(AB25,O25+AM25-Y25))) -> 0 | AD25: =AB25*($G$9/12) -> 83333.333 | AE25: =AE24-AF24 -> 31771609 | AF25: =IF(AE25>N25,N25,AE25) -> 113271.36 | AG25: =AE25*($G$3/12) -> 132381.7 | AH25: =AH24-AI24 -> 13950000 | AI25: =IF(AE25>N25,0,MIN(AH25,N25-AE25)) -> 0 | AJ25: =AH25*($G$6/12) -> 58125 | AK25: =IF(AL24=0,AK24+AM24,AK24-AL24) -> 24708811 | AL25: =MIN(IF(AB25>0,IF(AB25>O25,0,MIN(AK25,O25-AB25)),O25),AK25) -> 0 | AM25: =AK25*($G$7/12) -> 102953.38 | AN25: =FORECAST(B25, $AM$2:$AY$2,$AM$1:$AY$1) -> 0.022573694 | AO25: =Q25+R25 -> 113333.33 | AP25: =Q25*B25 -> 754991.45 | AQ25: =1/(1+(AN25+$CB$5)/12)^$B25 -> 0.96861202 | AR25: =T25+U25 -> 790257.86 | AS25: =T25*A25 -> 6405155.9 | AT25: =1/(1+(AN25+$BV$5)/12)^$B25 -> 0.97080722 | AU25: =W25+X25 -> 58333.333 | AV25: =W25*A25 -> 0 | AW25: =1/(1+(AN25+$BW$5)/12)^$B25 -> 0.97184997 | AX25: =IF(Y26>Y25,0,Z25+AA25) -> 0 | AY25: =A25*Z25 -> 0 | AZ25: =1/(1+(AN25+$BZ$5)/12)^$B25 -> 0.97923472 | BA25: =AC25+AD25 -> 83333.333 | BB25: =AC25*A25 -> 0 | BC25: =1/(1+(AN25+$CA$5)/12)^$B25 -> 0.9748143 | BD25: =AF25+AG25 -> 245653.07 | BE25: =AF25*A25 -> 1472527.7 | BF25: =1/(1+(AN25+$BU$5)/12)^$B25 -> 0.97290633 | BG25: =AI25+AJ25 -> 58125 | BH25: =AI25*A25 -> 0 | BI25: =1/(1+(AN25+$BX$5)/12)^$B25 -> 0.97625248 | BJ25: =IF(AK26>AK25,0,AL25+AM25) -> 0 | BK25: =A25*AL25 -> 0 | BL25: =1/(1+(AN25+$BY$5)/12)^$B25 -> 0.97788175 | BM25: =AO25+AR25+AU25+AX25+BA25+BD25+BG25+BJ25 -> 1349035.9 | BN25: =M25*B25 -> 4024178.3 | BO25: =1/(1+(AN25+$CC$5)/12)^$B25 -> 0.97433499
A26: 14 | B26: 9 | C26: =P26+S26+V26+Y26+AB26+AE26+AH26+AK26 -> 2.0254025e+08 | D26: =C26-E26 -> 0 | E26: =E25-H25-K25 -> 2.0254025e+08 | F26: =PMT($K$13/12,$K$12-B26+1,-E26,0) -> 1444804.7 | G26: =E26*$K$13/12 -> 939449.2 | H26: =F26-G26 -> 505355.47 | I26: =IF(A26<=(30-(240-$K$8)),((A26+(240-$K$7))/30)*$K$6,$K$6)*($K$5/100) -> 0 | J26: =1-(1-I26)^(1/12) -> 0 | K26: =(E26-H26)*J26 -> 0 | L26: =K26+H26+G26 -> 1444804.7 | M26: =L26-G26 -> 505355.47 | N26: =M26*$M$4 -> 113796.75 | O26: =M26*$M$5 -> 391558.72 | P26: =P25-Q25 -> 4455882.6 | Q26: =MIN(IF(S26>O26,0,MIN(P26,O26-S26))+IF(P26>0,MIN(AA26,P26)),P26) -> 94767.156 | R26: =P26*($G$10/12) -> 18566.178 | S26: =S25-T25 -> 70920150 | T26: =MIN(IF(S26>O26,O26,S26)+IF(S26>0,AM26,0),S26) -> 494941.07 | U26: =S26*($G$4/12) -> 295500.63 | V26: =V25-W25 -> 14000000 | W26: =IF(T26+P26<=O26+AM26+AA26,MIN(V26,O26-Q26+AA26-T26+AM26),0) -> 0 | X26: =V26*($G$5/12) -> 58333.333 | Y26: =IF(V25>O25,(IF(V25>AA25+O25+AM25,Y25+AA25,Y25+AA25-((AA25+O25+AM25)-V25))),Y25-Z25) -> 22744117 | Z26: =MIN(IF(V26>O26,0,MIN(Y26,O26-V26))+IF(AM25>V25,AM25,0),Y26) -> 0 | AA26: =Y26*($G$8/12) -> 94767.156 | AB26: =AB25-AC25 -> 20000000 | AC26: =MIN(IF(Y26>O26,0,MIN(AB26,O26+AM26-Y26))) -> 0 | AD26: =AB26*($G$9/12) -> 83333.333 | AE26: =AE25-AF25 -> 31658338 | AF26: =IF(AE26>N26,N26,AE26) -> 113796.75 | AG26: =AE26*($G$3/12) -> 131909.74 | AH26: =AH25-AI25 -> 13950000 | AI26: =IF(AE26>N26,0,MIN(AH26,N26-AE26)) -> 0 | AJ26: =AH26*($G$6/12) -> 58125 | AK26: =IF(AL25=0,AK25+AM25,AK25-AL25) -> 24811764 | AL26: =MIN(IF(AB26>0,IF(AB26>O26,0,MIN(AK26,O26-AB26)),O26),AK26) -> 0 | AM26: =AK26*($G$7/12) -> 103382.35 | AN26: =FORECAST(B26, $AM$2:$AY$2,$AM$1:$AY$1) -> 0.022654101 | AO26: =Q26+R26 -> 113333.33 | AP26: =Q26*B26 -> 852904.4 | AQ26: =1/(1+(AN26+$CB$5)/12)^$B26 -> 0.96470049 | AR26: =T26+U26 -> 790441.69 | AS26: =T26*A26 -> 6929175 | AT26: =1/(1+(AN26+$BV$5)/12)^$B26 -> 0.96716045 | AU26: =W26+X26 -> 58333.333 | AV26: =W26*A26 -> 0 | AW26: =1/(1+(AN26+$BW$5)/12)^$B26 -> 0.96832921 | AX26: =IF(Y27>Y26,0,Z26+AA26) -> 0 | AY26: =A26*Z26 -> 0 | AZ26: =1/(1+(AN26+$BZ$5)/12)^$B26 -> 0.97661082 | BA26: =AC26+AD26 -> 83333.333 | BB26: =AC26*A26 -> 0 | BC26: =1/(1+(AN26+$CA$5)/12)^$B26 -> 0.97165261 | BD26: =AF26+AG26 -> 245706.49 | BE26: =AF26*A26 -> 1593154.5 | BF26: =1/(1+(AN26+$BU$5)/12)^$B26 -> 0.96951338 | BG26: =AI26+AJ26 -> 58125 | BH26: =AI26*A26 -> 0 | BI26: =1/(1+(AN26+$BX$5)/12)^$B26 -> 0.97326546 | BJ26: =IF(AK27>AK26,0,AL26+AM26) -> 0 | BK26: =A26*AL26 -> 0 | BL26: =1/(1+(AN26+$BY$5)/12)^$B26 -> 0.97509295 | BM26: =AO26+AR26+AU26+AX26+BA26+BD26+BG26+BJ26 -> 1349273.2 | BN26: =M26*B26 -> 4548199.2 | BO26: =1/(1+(AN26+$CC$5)/12)^$B26 -> 0.97111515
A27: 15 | B27: 10 | C27: =P27+S27+V27+Y27+AB27+AE27+AH27+AK27 -> 2.020349e+08 | D27: =C27-E27 -> 0 | E27: =E26-H26-K26 -> 2.020349e+08 | F27: =PMT($K$13/12,$K$12-B27+1,-E27,0) -> 1444804.7 | G27: =E27*$K$13/12 -> 937105.2 | H27: =F27-G27 -> 507699.48 | I27: =IF(A27<=(30-(240-$K$8)),((A27+(240-$K$7))/30)*$K$6,$K$6)*($K$5/100) -> 0 | J27: =1-(1-I27)^(1/12) -> 0 | K27: =(E27-H27)*J27 -> 0 | L27: =K27+H27+G27 -> 1444804.7 | M27: =L27-G27 -> 507699.48 | N27: =M27*$M$4 -> 114324.58 | O27: =M27*$M$5 -> 393374.9 | P27: =P26-Q26 -> 4361115.5 | Q27: =MIN(IF(S27>O27,0,MIN(P27,O27-S27))+IF(P27>0,MIN(AA27,P27)),P27) -> 95162.019 | R27: =P27*($G$10/12) -> 18171.315 | S27: =S26-T26 -> 70425209 | T27: =MIN(IF(S27>O27,O27,S27)+IF(S27>0,AM27,0),S27) -> 497188.01 | U27: =S27*($G$4/12) -> 293438.37 | V27: =V26-W26 -> 14000000 | W27: =IF(T27+P27<=O27+AM27+AA27,MIN(V27,O27-Q27+AA27-T27+AM27),0) -> 0 | X27: =V27*($G$5/12) -> 58333.333 | Y27: =IF(V26>O26,(IF(V26>AA26+O26+AM26,Y26+AA26,Y26+AA26-((AA26+O26+AM26)-V26))),Y26-Z26) -> 22838885 | Z27: =MIN(IF(V27>O27,0,MIN(Y27,O27-V27))+IF(AM26>V26,AM26,0),Y27) -> 0 | AA27: =Y27*($G$8/12) -> 95162.019 | AB27: =AB26-AC26 -> 20000000 | AC27: =MIN(IF(Y27>O27,0,MIN(AB27,O27+AM27-Y27))) -> 0 | AD27: =AB27*($G$9/12) -> 83333.333 | AE27: =AE26-AF26 -> 31544541 | AF27: =IF(AE27>N27,N27,AE27) -> 114324.58 | AG27: =AE27*($G$3/12) -> 131435.59 | AH27: =AH26-AI26 -> 13950000 | AI27: =IF(AE27>N27,0,MIN(AH27,N27-AE27)) -> 0 | AJ27: =AH27*($G$6/12) -> 58125 | AK27: =IF(AL26=0,AK26+AM26,AK26-AL26) -> 24915147 | AL27: =MIN(IF(AB27>0,IF(AB27>O27,0,MIN(AK27,O27-AB27)),O27),AK27) -> 0 | AM27: =AK27*($G$7/12) -> 103813.11 | AN27: =FORECAST(B27, $AM$2:$AY$2,$AM$1:$AY$1) -> 0.022734509 | AO27: =Q27+R27 -> 113333.33 | AP27: =Q27*B27 -> 951620.19 | AQ27: =1/(1+(AN27+$CB$5)/12)^$B27 -> 0.96079194 | AR27: =T27+U27 -> 790626.38 | AS27: =T27*A27 -> 7457820.1 | AT27: =1/(1+(AN27+$BV$5)/12)^$B27 -> 0.96351452 | AU27: =W27+X27 -> 58333.333 | AV27: =W27*A27 -> 0 | AW27: =1/(1+(AN27+$BW$5)/12)^$B27 -> 0.96480832 | AX27: =IF(Y28>Y27,0,Z27+AA27) -> 0 | AY27: =A27*Z27 -> 0 | AZ27: =1/(1+(AN27+$BZ$5)/12)^$B27 -> 0.97398093 | BA27: =AC27+AD27 -> 83333.333 | BB27: =AC27*A27 -> 0 | BC27: =1/(1+(AN27+$CA$5)/12)^$B27 -> 0.96848824 | BD27: =AF27+AG27 -> 245760.17 | BE27: =AF27*A27 -> 1714868.7 | BF27: =1/(1+(AN27+$BU$5)/12)^$B27 -> 0.96611936 | BG27: =AI27+AJ27 -> 58125 | BH27: =AI27*A27 -> 0 | BI27: =1/(1+(AN27+$BX$5)/12)^$B27 -> 0.9702746 | BJ27: =IF(AK28>AK27,0,AL27+AM27) -> 0 | BK27: =A27*AL27 -> 0 | BL27: =1/(1+(AN27+$BY$5)/12)^$B27 -> 0.97229911 | BM27: =AO27+AR27+AU27+AX27+BA27+BD27+BG27+BJ27 -> 1349511.5 | BN27: =M27*B27 -> 5076994.8 | BO27: =1/(1+(AN27+$CC$5)/12)^$B27 -> 0.96789303
A28: 16 | B28: 11 | C28: =P28+S28+V28+Y28+AB28+AE28+AH28+AK28 -> 2.015272e+08 | D28: =C28-E28 -> 0 | E28: =E27-H27-K27 -> 2.015272e+08 | F28: =PMT($K$13/12,$K$12-B28+1,-E28,0) -> 1444804.7 | G28: =E28*$K$13/12 -> 934750.32 | H28: =F28-G28 -> 510054.35 | I28: =IF(A28<=(30-(240-$K$8)),((A28+(240-$K$7))/30)*$K$6,$K$6)*($K$5/100) -> 0 | J28: =1-(1-I28)^(1/12) -> 0 | K28: =(E28-H28)*J28 -> 0 | L28: =K28+H28+G28 -> 1444804.7 | M28: =L28-G28 -> 510054.35 | N28: =M28*$M$4 -> 114854.85 | O28: =M28*$M$5 -> 395199.5 | P28: =P27-Q27 -> 4265953.5 | Q28: =MIN(IF(S28>O28,0,MIN(P28,O28-S28))+IF(P28>0,MIN(AA28,P28)),P28) -> 95558.527 | R28: =P28*($G$10/12) -> 17774.806 | S28: =S27-T27 -> 69928021 | T28: =MIN(IF(S28>O28,O28,S28)+IF(S28>0,AM28,0),S28) -> 499445.17 | U28: =S28*($G$4/12) -> 291366.75 | V28: =V27-W27 -> 14000000 | W28: =IF(T28+P28<=O28+AM28+AA28,MIN(V28,O28-Q28+AA28-T28+AM28),0) -> 0 | X28: =V28*($G$5/12) -> 58333.333 | Y28: =IF(V27>O27,(IF(V27>AA27+O27+AM27,Y27+AA27,Y27+AA27-((AA27+O27+AM27)-V27))),Y27-Z27) -> 22934047 | Z28: =MIN(IF(V28>O28,0,MIN(Y28,O28-V28))+IF(AM27>V27,AM27,0),Y28) -> 0 | AA28: =Y28*($G$8/12) -> 95558.527 | AB28: =AB27-AC27 -> 20000000 | AC28: =MIN(IF(Y28>O28,0,MIN(AB28,O28+AM28-Y28))) -> 0 | AD28: =AB28*($G$9/12) -> 83333.333 | AE28: =AE27-AF27 -> 31430216 | AF28: =IF(AE28>N28,N28,AE28) -> 114854.85 | AG28: =AE28*($G$3/12) -> 130959.23 | AH28: =AH27-AI27 -> 13950000 | AI28: =IF(AE28>N28,0,MIN(AH28,N28-AE28)) -> 0 | AJ28: =AH28*($G$6/12) -> 58125 | AK28: =IF(AL27=0,AK27+AM27,AK27-AL27) -> 25018960 | AL28: =MIN(IF(AB28>0,IF(AB28>O28,0,MIN(AK28,O28-AB28)),O28),AK28) -> 0 | AM28: =AK28*($G$7/12) -> 104245.67 | AN28: =FORECAST(B28, $AM$2:$AY$2,$AM$1:$AY$1) -> 0.022814916 | AO28: =Q28+R28 -> 113333.33 | AP28: =Q28*B28 -> 1051143.8 | AQ28: =1/(1+(AN28+$CB$5)/12)^$B28 -> 0.95688644 | AR28: =T28+U28 -> 790811.92 | AS28: =T28*A28 -> 7991122.7 | AT28: =1/(1+(AN28+$BV$5)/12)^$B28 -> 0.95986951 | AU28: =W28+X28 -> 58333.333 | AV28: =W28*A28 -> 0 | AW28: =1/(1+(AN28+$BW$5)/12)^$B28 -> 0.9612874 | AX28: =IF(Y29>Y28,0,Z28+AA28) -> 0 | AY28: =A28*Z28 -> 0 | AZ28: =1/(1+(AN28+$BZ$5)/12)^$B28 -> 0.97134515 | BA28: =AC28+AD28 -> 83333.333 | BB28: =AC28*A28 -> 0 | BC28: =1/(1+(AN28+$CA$5)/12)^$B28 -> 0.96532128 | BD28: =AF28+AG28 -> 245814.09 | BE28: =AF28*A28 -> 1837677.7 | BF28: =1/(1+(AN28+$BU$5)/12)^$B28 -> 0.96272437 | BG28: =AI28+AJ28 -> 58125 | BH28: =AI28*A28 -> 0 | BI28: =1/(1+(AN28+$BX$5)/12)^$B28 -> 0.96728002 | BJ28: =IF(AK29>AK28,0,AL28+AM28) -> 0 | BK28: =A28*AL28 -> 0 | BL28: =1/(1+(AN28+$BY$5)/12)^$B28 -> 0.96950032 | BM28: =AO28+AR28+AU28+AX28+BA28+BD28+BG28+BJ28 -> 1349751 | BN28: =M28*B28 -> 5610597.9 | BO28: =1/(1+(AN28+$CC$5)/12)^$B28 -> 0.96466871
A29: 17 | B29: 12 | C29: =P29+S29+V29+Y29+AB29+AE29+AH29+AK29 -> 2.0101714e+08 | D29: =C29-E29 -> 0 | E29: =E28-H28-K28 -> 2.0101714e+08 | F29: =PMT($K$13/12,$K$12-B29+1,-E29,0) -> 1444804.7 | G29: =E29*$K$13/12 -> 932384.51 | H29: =F29-G29 -> 512420.16 | I29: =IF(A29<=(30-(240-$K$8)),((A29+(240-$K$7))/30)*$K$6,$K$6)*($K$5/100) -> 0 | J29: =1-(1-I29)^(1/12) -> 0 | K29: =(E29-H29)*J29 -> 0 | L29: =K29+H29+G29 -> 1444804.7 | M29: =L29-G29 -> 512420.16 | N29: =M29*$M$4 -> 115387.59 | O29: =M29*$M$5 -> 397032.57 | P29: =P28-Q28 -> 4170394.9 | Q29: =MIN(IF(S29>O29,0,MIN(P29,O29-S29))+IF(P29>0,MIN(AA29,P29)),P29) -> 95956.688 | R29: =P29*($G$10/12) -> 17376.646 | S29: =S28-T28 -> 69428576 | T29: =MIN(IF(S29>O29,O29,S29)+IF(S29>0,AM29,0),S29) -> 501712.59 | U29: =S29*($G$4/12) -> 289285.73 | V29: =V28-W28 -> 14000000 | W29: =IF(T29+P29<=O29+AM29+AA29,MIN(V29,O29-Q29+AA29-T29+AM29),0) -> 0 | X29: =V29*($G$5/12) -> 58333.333 | Y29: =IF(V28>O28,(IF(V28>AA28+O28+AM28,Y28+AA28,Y28+AA28-((AA28+O28+AM28)-V28))),Y28-Z28) -> 23029605 | Z29: =MIN(IF(V29>O29,0,MIN(Y29,O29-V29))+IF(AM28>V28,AM28,0),Y29) -> 0 | AA29: =Y29*($G$8/12) -> 95956.688 | AB29: =AB28-AC28 -> 20000000 | AC29: =MIN(IF(Y29>O29,0,MIN(AB29,O29+AM29-Y29))) -> 0 | AD29: =AB29*($G$9/12) -> 83333.333 | AE29: =AE28-AF28 -> 31315361 | AF29: =IF(AE29>N29,N29,AE29) -> 115387.59 | AG29: =AE29*($G$3/12) -> 130480.67 | AH29: =AH28-AI28 -> 13950000 | AI29: =IF(AE29>N29,0,MIN(AH29,N29-AE29)) -> 0 | AJ29: =AH29*($G$6/12) -> 58125 | AK29: =IF(AL28=0,AK28+AM28,AK28-AL28) -> 25123206 | AL29: =MIN(IF(AB29>0,IF(AB29>O29,0,MIN(AK29,O29-AB29)),O29),AK29) -> 0 | AM29: =AK29*($G$7/12) -> 104680.02 | AN29: =FORECAST(B29, $AM$2:$AY$2,$AM$1:$AY$1) -> 0.022895323 | AO29: =Q29+R29 -> 113333.33 | AP29: =Q29*B29 -> 1151480.3 | AQ29: =1/(1+(AN29+$CB$5)/12)^$B29 -> 0.95298411 | AR29: =T29+U29 -> 790998.32 | AS29: =T29*A29 -> 8529114 | AT29: =1/(1+(AN29+$BV$5)/12)^$B29 -> 0.95622553 | AU29: =W29+X29 -> 58333.333 | AV29: =W29*A29 -> 0 | AW29: =1/(1+(AN29+$BW$5)/12)^$B29 -> 0.95776653 | AX29: =IF(Y30>Y29,0,Z29+AA29) -> 0 | AY29: =A29*Z29 -> 0 | AZ29: =1/(1+(AN29+$BZ$5)/12)^$B29 -> 0.96870354 | BA29: =AC29+AD29 -> 83333.333 | BB29: =AC29*A29 -> 0 | BC29: =1/(1+(AN29+$CA$5)/12)^$B29 -> 0.96215182 | BD29: =AF29+AG29 -> 245868.26 | BE29: =AF29*A29 -> 1961589 | BF29: =1/(1+(AN29+$BU$5)/12)^$B29 -> 0.95932849 | BG29: =AI29+AJ29 -> 58125 | BH29: =AI29*A29 -> 0 | BI29: =1/(1+(AN29+$BX$5)/12)^$B29 -> 0.96428179 | BJ29: =IF(AK30>AK29,0,AL29+AM29) -> 0 | BK29: =A29*AL29 -> 0 | BL29: =1/(1+(AN29+$BY$5)/12)^$B29 -> 0.96669666 | BM29: =AO29+AR29+AU29+AX29+BA29+BD29+BG29+BJ29 -> 1349991.6 | BN29: =M29*B29 -> 6149041.9 | BO29: =1/(1+(AN29+$CC$5)/12)^$B29 -> 0.96144229
A30: 18 | B30: 13 | C30: =P30+S30+V30+Y30+AB30+AE30+AH30+AK30 -> 2.0050472e+08 | D30: =C30-E30 -> 0 | E30: =E29-H29-K29 -> 2.0050472e+08 | F30: =PMT($K$13/12,$K$12-B30+1,-E30,0) -> 1444804.7 | G30: =E30*$K$13/12 -> 930007.74 | H30: =F30-G30 -> 514796.93 | I30: =IF(A30<=(30-(240-$K$8)),((A30+(240-$K$7))/30)*$K$6,$K$6)*($K$5/100) -> 0 | J30: =1-(1-I30)^(1/12) -> 0 | K30: =(E30-H30)*J30 -> 0 | L30: =K30+H30+G30 -> 1444804.7 | M30: =L30-G30 -> 514796.93 | N30: =M30*$M$4 -> 115922.8 | O30: =M30*$M$5 -> 398874.14 | P30: =P29-Q29 -> 4074438.2 | Q30: =MIN(IF(S30>O30,0,MIN(P30,O30-S30))+IF(P30>0,MIN(AA30,P30)),P30) -> 96356.507 | R30: =P30*($G$10/12) -> 16976.826 | S30: =S29-T29 -> 68926863 | T30: =MIN(IF(S30>O30,O30,S30)+IF(S30>0,AM30,0),S30) -> 503990.33 | U30: =S30*($G$4/12) -> 287195.26 | V30: =V29-W29 -> 14000000 | W30: =IF(T30+P30<=O30+AM30+AA30,MIN(V30,O30-Q30+AA30-T30+AM30),0) -> 0 | X30: =V30*($G$5/12) -> 58333.333 | Y30: =IF(V29>O29,(IF(V29>AA29+O29+AM29,Y29+AA29,Y29+AA29-((AA29+O29+AM29)-V29))),Y29-Z29) -> 23125562 | Z30: =MIN(IF(V30>O30,0,MIN(Y30,O30-V30))+IF(AM29>V29,AM29,0),Y30) -> 0 | AA30: =Y30*($G$8/12) -> 96356.507 | AB30: =AB29-AC29 -> 20000000 | AC30: =MIN(IF(Y30>O30,0,MIN(AB30,O30+AM30-Y30))) -> 0 | AD30: =AB30*($G$9/12) -> 83333.333 | AE30: =AE29-AF29 -> 31199974 | AF30: =IF(AE30>N30,N30,AE30) -> 115922.8 | AG30: =AE30*($G$3/12) -> 129999.89 | AH30: =AH29-AI29 -> 13950000 | AI30: =IF(AE30>N30,0,MIN(AH30,N30-AE30)) -> 0 | AJ30: =AH30*($G$6/12) -> 58125 | AK30: =IF(AL29=0,AK29+AM29,AK29-AL29) -> 25227886 | AL30: =MIN(IF(AB30>0,IF(AB30>O30,0,MIN(AK30,O30-AB30)),O30),AK30) -> 0 | AM30: =AK30*($G$7/12) -> 105116.19 | AN30: =FORECAST(B30, $AM$2:$AY$2,$AM$1:$AY$1) -> 0.02297573 | AO30: =Q30+R30 -> 113333.33 | AP30: =Q30*B30 -> 1252634.6 | AQ30: =1/(1+(AN30+$CB$5)/12)^$B30 -> 0.94908502 | AR30: =T30+U30 -> 791185.59 | AS30: =T30*A30 -> 9071825.9 | AT30: =1/(1+(AN30+$BV$5)/12)^$B30 -> 0.95258266 | AU30: =W30+X30 -> 58333.333 | AV30: =W30*A30 -> 0 | AW30: =1/(1+(AN30+$BW$5)/12)^$B30 -> 0.95424582 | AX30: =IF(Y31>Y30,0,Z30+AA30) -> 0 | AY30: =A30*Z30 -> 0 | AZ30: =1/(1+(AN30+$BZ$5)/12)^$B30 -> 0.96605622 | BA30: =AC30+AD30 -> 83333.333 | BB30: =AC30*A30 -> 0 | BC30: =1/(1+(AN30+$CA$5)/12)^$B30 -> 0.95897996 | BD30: =AF30+AG30 -> 245922.69 | BE30: =AF30*A30 -> 2086610.3 | BF30: =1/(1+(AN30+$BU$5)/12)^$B30 -> 0.95593183 | BG30: =AI30+AJ30 -> 58125 | BH30: =AI30*A30 -> 0 | BI30: =1/(1+(AN30+$BX$5)/12)^$B30 -> 0.96128002 | BJ30: =IF(AK31>AK30,0,AL30+AM30) -> 0 | BK30: =A30*AL30 -> 0 | BL30: =1/(1+(AN30+$BY$5)/12)^$B30 -> 0.96388824 | BM30: =AO30+AR30+AU30+AX30+BA30+BD30+BG30+BJ30 -> 1350233.3 | BN30: =M30*B30 -> 6692360.1 | BO30: =1/(1+(AN30+$CC$5)/12)^$B30 -> 0.95821387
A31: 19 | B31: 14 | C31: =P31+S31+V31+Y31+AB31+AE31+AH31+AK31 -> 1.9998993e+08 | D31: =C31-E31 -> 0 | E31: =E30-H30-K30 -> 1.9998993e+08 | F31: =PMT($K$13/12,$K$12-B31+1,-E31,0) -> 1444804.7 | G31: =E31*$K$13/12 -> 927619.94 | H31: =F31-G31 -> 517184.73 | I31: =IF(A31<=(30-(240-$K$8)),((A31+(240-$K$7))/30)*$K$6,$K$6)*($K$5/100) -> 0 | J31: =1-(1-I31)^(1/12) -> 0 | K31: =(E31-H31)*J31 -> 0 | L31: =K31+H31+G31 -> 1444804.7 | M31: =L31-G31 -> 517184.73 | N31: =M31*$M$4 -> 116460.48 | O31: =M31*$M$5 -> 400724.25 | P31: =P30-Q30 -> 3978081.7 | Q31: =MIN(IF(S31>O31,0,MIN(P31,O31-S31))+IF(P31>0,MIN(AA31,P31)),P31) -> 96757.993 | R31: =P31*($G$10/12) -> 16575.341 | S31: =S30-T30 -> 68422873 | T31: =MIN(IF(S31>O31,O31,S31)+IF(S31>0,AM31,0),S31) -> 506278.42 | U31: =S31*($G$4/12) -> 285095.3 | V31: =V30-W30 -> 14000000 | W31: =IF(T31+P31<=O31+AM31+AA31,MIN(V31,O31-Q31+AA31-T31+AM31),0) -> 0 | X31: =V31*($G$5/12) -> 58333.333 | Y31: =IF(V30>O30,(IF(V30>AA30+O30+AM30,Y30+AA30,Y30+AA30-((AA30+O30+AM30)-V30))),Y30-Z30) -> 23221918 | Z31: =MIN(IF(V31>O31,0,MIN(Y31,O31-V31))+IF(AM30>V30,AM30,0),Y31) -> 0 | AA31: =Y31*($G$8/12) -> 96757.993 | AB31: =AB30-AC30 -> 20000000 | AC31: =MIN(IF(Y31>O31,0,MIN(AB31,O31+AM31-Y31))) -> 0 | AD31: =AB31*($G$9/12) -> 83333.333 | AE31: =AE30-AF30 -> 31084051 | AF31: =IF(AE31>N31,N31,AE31) -> 116460.48 | AG31: =AE31*($G$3/12) -> 129516.88 | AH31: =AH30-AI30 -> 13950000 | AI31: =IF(AE31>N31,0,MIN(AH31,N31-AE31)) -> 0 | AJ31: =AH31*($G$6/12) -> 58125 | AK31: =IF(AL30=0,AK30+AM30,AK30-AL30) -> 25333002 | AL31: =MIN(IF(AB31>0,IF(AB31>O31,0,MIN(AK31,O31-AB31)),O31),AK31) -> 0 | AM31: =AK31*($G$7/12) -> 105554.17 | AN31: =FORECAST(B31, $AM$2:$AY$2,$AM$1:$AY$1) -> 0.023056137 | AO31: =Q31+R31 -> 113333.33 | AP31: =Q31*B31 -> 1354611.9 | AQ31: =1/(1+(AN31+$CB$5)/12)^$B31 -> 0.94518926 | AR31: =T31+U31 -> 791373.73 | AS31: =T31*A31 -> 9619290 | AT31: =1/(1+(AN31+$BV$5)/12)^$B31 -> 0.94894101 | AU31: =W31+X31 -> 58333.333 | AV31: =W31*A31 -> 0 | AW31: =1/(1+(AN31+$BW$5)/12)^$B31 -> 0.95072536 | AX31: =IF(Y32>Y31,0,Z31+AA31) -> 0 | AY31: =A31*Z31 -> 0 | AZ31: =1/(1+(AN31+$BZ$5)/12)^$B31 -> 0.96340325 | BA31: =AC31+AD31 -> 83333.333 | BB31: =AC31*A31 -> 0 | BC31: =1/(1+(AN31+$CA$5)/12)^$B31 -> 0.95580578 | BD31: =AF31+AG31 -> 245977.36 | BE31: =AF31*A31 -> 2212749.2 | BF31: =1/(1+(AN31+$BU$5)/12)^$B31 -> 0.95253447 | BG31: =AI31+AJ31 -> 58125 | BH31: =AI31*A31 -> 0 | BI31: =1/(1+(AN31+$BX$5)/12)^$B31 -> 0.95827479 | BJ31: =IF(AK32>AK31,0,AL31+AM31) -> 0 | BK31: =A31*AL31 -> 0 | BL31: =1/(1+(AN31+$BY$5)/12)^$B31 -> 0.96107513 | BM31: =AO31+AR31+AU31+AX31+BA31+BD31+BG31+BJ31 -> 1350476.1 | BN31: =M31*B31 -> 7240586.3 | BO31: =1/(1+(AN31+$CC$5)/12)^$B31 -> 0.95498352
A32: 20 | B32: 15 | C32: =P32+S32+V32+Y32+AB32+AE32+AH32+AK32 -> 1.9947274e+08 | D32: =C32-E32 -> 0 | E32: =E31-H31-K31 -> 1.9947274e+08 | F32: =PMT($K$13/12,$K$12-B32+1,-E32,0) -> 1444804.7 | G32: =E32*$K$13/12 -> 925221.06 | H32: =F32-G32 -> 519583.61 | I32: =IF(A32<=(30-(240-$K$8)),((A32+(240-$K$7))/30)*$K$6,$K$6)*($K$5/100) -> 0 | J32: =1-(1-I32)^(1/12) -> 0 | K32: =(E32-H32)*J32 -> 0 | L32: =K32+H32+G32 -> 1444804.7 | M32: =L32-G32 -> 519583.61 | N32: =M32*$M$4 -> 117000.67 | O32: =M32*$M$5 -> 402582.94 | P32: =P31-Q31 -> 3881323.7 | Q32: =MIN(IF(S32>O32,0,MIN(P32,O32-S32))+IF(P32>0,MIN(AA32,P32)),P32) -> 97161.151 | R32: =P32*($G$10/12) -> 16172.182 | S32: =S31-T31 -> 67916595 | T32: =MIN(IF(S32>O32,O32,S32)+IF(S32>0,AM32,0),S32) -> 508576.92 | U32: =S32*($G$4/12) -> 282985.81 | V32: =V31-W31 -> 14000000 | W32: =IF(T32+P32<=O32+AM32+AA32,MIN(V32,O32-Q32+AA32-T32+AM32),0) -> 0 | X32: =V32*($G$5/12) -> 58333.333 | Y32: =IF(V31>O31,(IF(V31>AA31+O31+AM31,Y31+AA31,Y31+AA31-((AA31+O31+AM31)-V31))),Y31-Z31) -> 23318676 | Z32: =MIN(IF(V32>O32,0,MIN(Y32,O32-V32))+IF(AM31>V31,AM31,0),Y32) -> 0 | AA32: =Y32*($G$8/12) -> 97161.151 | AB32: =AB31-AC31 -> 20000000 | AC32: =MIN(IF(Y32>O32,0,MIN(AB32,O32+AM32-Y32))) -> 0 | AD32: =AB32*($G$9/12) -> 83333.333 | AE32: =AE31-AF31 -> 30967591 | AF32: =IF(AE32>N32,N32,AE32) -> 117000.67 | AG32: =AE32*($G$3/12) -> 129031.63 | AH32: =AH31-AI31 -> 13950000 | AI32: =IF(AE32>N32,0,MIN(AH32,N32-AE32)) -> 0 | AJ32: =AH32*($G$6/12) -> 58125 | AK32: =IF(AL31=0,AK31+AM31,AK31-AL31) -> 25438556 | AL32: =MIN(IF(AB32>0,IF(AB32>O32,0,MIN(AK32,O32-AB32)),O32),AK32) -> 0 | AM32: =AK32*($G$7/12) -> 105993.98 | AN32: =FORECAST(B32, $AM$2:$AY$2,$AM$1:$AY$1) -> 0.023136544 | AO32: =Q32+R32 -> 113333.33 | AP32: =Q32*B32 -> 1457417.3 | AQ32: =1/(1+(AN32+$CB$5)/12)^$B32 -> 0.94129694 | AR32: =T32+U32 -> 791562.73 | AS32: =T32*A32 -> 10171538 | AT32: =1/(1+(AN32+$BV$5)/12)^$B32 -> 0.94530065 | AU32: =W32+X32 -> 58333.333 | AV32: =W32*A32 -> 0 | AW32: =1/(1+(AN32+$BW$5)/12)^$B32 -> 0.94720524 | AX32: =IF(Y33>Y32,0,Z32+AA32) -> 0 | AY32: =A32*Z32 -> 0 | AZ32: =1/(1+(AN32+$BZ$5)/12)^$B32 -> 0.96074472 | BA32: =AC32+AD32 -> 83333.333 | BB32: =AC32*A32 -> 0 | BC32: =1/(1+(AN32+$CA$5)/12)^$B32 -> 0.95262939 | BD32: =AF32+AG32 -> 246032.29 | BE32: =AF32*A32 -> 2340013.3 | BF32: =1/(1+(AN32+$BU$5)/12)^$B32 -> 0.94913651 | BG32: =AI32+AJ32 -> 58125 | BH32: =AI32*A32 -> 0 | BI32: =1/(1+(AN32+$BX$5)/12)^$B32 -> 0.95526619 | BJ32: =IF(AK33>AK32,0,AL32+AM32) -> 0 | BK32: =A32*AL32 -> 0 | BL32: =1/(1+(AN32+$BY$5)/12)^$B32 -> 0.95825743 | BM32: =AO32+AR32+AU32+AX32+BA32+BD32+BG32+BJ32 -> 1350720 | BN32: =M32*B32 -> 7793754.1 | BO32: =1/(1+(AN32+$CC$5)/12)^$B32 -> 0.95175136
A33: 21 | B33: 16 | C33: =P33+S33+V33+Y33+AB33+AE33+AH33+AK33 -> 1.9895316e+08 | D33: =C33-E33 -> 0 | E33: =E32-H32-K32 -> 1.9895316e+08 | F33: =PMT($K$13/12,$K$12-B33+1,-E33,0) -> 1444804.7 | G33: =E33*$K$13/12 -> 922811.06 | H33: =F33-G33 -> 521993.61 | I33: =IF(A33<=(30-(240-$K$8)),((A33+(240-$K$7))/30)*$K$6,$K$6)*($K$5/100) -> 0 | J33: =1-(1-I33)^(1/12) -> 0 | K33: =(E33-H33)*J33 -> 0 | L33: =K33+H33+G33 -> 1444804.7 | M33: =L33-G33 -> 521993.61 | N33: =M33*$M$4 -> 117543.36 | O33: =M33*$M$5 -> 404450.25 | P33: =P32-Q32 -> 3784162.6 | Q33: =MIN(IF(S33>O33,0,MIN(P33,O33-S33))+IF(P33>0,MIN(AA33,P33)),P33) -> 97565.989 | R33: =P33*($G$10/12) -> 15767.344 | S33: =S32-T32 -> 67408018 | T33: =MIN(IF(S33>O33,O33,S33)+IF(S33>0,AM33,0),S33) -> 510885.88 | U33: =S33*($G$4/12) -> 280866.74 | V33: =V32-W32 -> 14000000 | W33: =IF(T33+P33<=O33+AM33+AA33,MIN(V33,O33-Q33+AA33-T33+AM33),0) -> 0 | X33: =V33*($G$5/12) -> 58333.333 | Y33: =IF(V32>O32,(IF(V32>AA32+O32+AM32,Y32+AA32,Y32+AA32-((AA32+O32+AM32)-V32))),Y32-Z32) -> 23415837 | Z33: =MIN(IF(V33>O33,0,MIN(Y33,O33-V33))+IF(AM32>V32,AM32,0),Y33) -> 0 | AA33: =Y33*($G$8/12) -> 97565.989 | AB33: =AB32-AC32 -> 20000000 | AC33: =MIN(IF(Y33>O33,0,MIN(AB33,O33+AM33-Y33))) -> 0 | AD33: =AB33*($G$9/12) -> 83333.333 | AE33: =AE32-AF32 -> 30850590 | AF33: =IF(AE33>N33,N33,AE33) -> 117543.36 | AG33: =AE33*($G$3/12) -> 128544.12 | AH33: =AH32-AI32 -> 13950000 | AI33: =IF(AE33>N33,0,MIN(AH33,N33-AE33)) -> 0 | AJ33: =AH33*($G$6/12) -> 58125 | AK33: =IF(AL32=0,AK32+AM32,AK32-AL32) -> 25544550 | AL33: =MIN(IF(AB33>0,IF(AB33>O33,0,MIN(AK33,O33-AB33)),O33),AK33) -> 0 | AM33: =AK33*($G$7/12) -> 106435.62 | AN33: =FORECAST(B33, $AM$2:$AY$2,$AM$1:$AY$1) -> 0.023216952 | AO33: =Q33+R33 -> 113333.33 | AP33: =Q33*B33 -> 1561055.8 | AQ33: =1/(1+(AN33+$CB$5)/12)^$B33 -> 0.93740813 | AR33: =T33+U33 -> 791752.62 | AS33: =T33*A33 -> 10728603 | AT33: =1/(1+(AN33+$BV$5)/12)^$B33 -> 0.94166169 | AU33: =W33+X33 -> 58333.333 | AV33: =W33*A33 -> 0 | AW33: =1/(1+(AN33+$BW$5)/12)^$B33 -> 0.94368555 | AX33: =IF(Y34>Y33,0,Z33+AA33) -> 0 | AY33: =A33*Z33 -> 0 | AZ33: =1/(1+(AN33+$BZ$5)/12)^$B33 -> 0.95808073 | BA33: =AC33+AD33 -> 83333.333 | BB33: =AC33*A33 -> 0 | BC33: =1/(1+(AN33+$CA$5)/12)^$B33 -> 0.94945087 | BD33: =AF33+AG33 -> 246087.48 | BE33: =AF33*A33 -> 2468410.5 | BF33: =1/(1+(AN33+$BU$5)/12)^$B33 -> 0.94573805 | BG33: =AI33+AJ33 -> 58125 | BH33: =AI33*A33 -> 0 | BI33: =1/(1+(AN33+$BX$5)/12)^$B33 -> 0.95225431 | BJ33: =IF(AK34>AK33,0,AL33+AM33) -> 0 | BK33: =A33*AL33 -> 0 | BL33: =1/(1+(AN33+$BY$5)/12)^$B33 -> 0.95543522 | BM33: =AO33+AR33+AU33+AX33+BA33+BD33+BG33+BJ33 -> 1350965.1 | BN33: =M33*B33 -> 8351897.8 | BO33: =1/(1+(AN33+$CC$5)/12)^$B33 -> 0.94851747
A34: 22 | B34: 17 | C34: =P34+S34+V34+Y34+AB34+AE34+AH34+AK34 -> 1.9843116e+08 | D34: =C34-E34 -> 0 | E34: =E33-H33-K33 -> 1.9843116e+08 | F34: =PMT($K$13/12,$K$12-B34+1,-E34,0) -> 1444804.7 | G34: =E34*$K$13/12 -> 920389.88 | H34: =F34-G34 -> 524414.79 | I34: =IF(A34<=(30-(240-$K$8)),((A34+(240-$K$7))/30)*$K$6,$K$6)*($K$5/100) -> 0 | J34: =1-(1-I34)^(1/12) -> 0 | K34: =(E34-H34)*J34 -> 0 | L34: =K34+H34+G34 -> 1444804.7 | M34: =L34-G34 -> 524414.79 | N34: =M34*$M$4 -> 118088.56 | O34: =M34*$M$5 -> 406326.23 | P34: =P33-Q33 -> 3686596.6 | Q34: =MIN(IF(S34>O34,0,MIN(P34,O34-S34))+IF(P34>0,MIN(AA34,P34)),P34) -> 97972.514 | R34: =P34*($G$10/12) -> 15360.819 | S34: =S33-T33 -> 66897132 | T34: =MIN(IF(S34>O34,O34,S34)+IF(S34>0,AM34,0),S34) -> 513205.34 | U34: =S34*($G$4/12) -> 278738.05 | V34: =V33-W33 -> 14000000 | W34: =IF(T34+P34<=O34+AM34+AA34,MIN(V34,O34-Q34+AA34-T34+AM34),0) -> 0 | X34: =V34*($G$5/12) -> 58333.333 | Y34: =IF(V33>O33,(IF(V33>AA33+O33+AM33,Y33+AA33,Y33+AA33-((AA33+O33+AM33)-V33))),Y33-Z33) -> 23513403 | Z34: =MIN(IF(V34>O34,0,MIN(Y34,O34-V34))+IF(AM33>V33,AM33,0),Y34) -> 0 | AA34: =Y34*($G$8/12) -> 97972.514 | AB34: =AB33-AC33 -> 20000000 | AC34: =MIN(IF(Y34>O34,0,MIN(AB34,O34+AM34-Y34))) -> 0 | AD34: =AB34*($G$9/12) -> 83333.333 | AE34: =AE33-AF33 -> 30733047 | AF34: =IF(AE34>N34,N34,AE34) -> 118088.56 | AG34: =AE34*($G$3/12) -> 128054.36 | AH34: =AH33-AI33 -> 13950000 | AI34: =IF(AE34>N34,0,MIN(AH34,N34-AE34)) -> 0 | AJ34: =AH34*($G$6/12) -> 58125 | AK34: =IF(AL33=0,AK33+AM33,AK33-AL33) -> 25650986 | AL34: =MIN(IF(AB34>0,IF(AB34>O34,0,MIN(AK34,O34-AB34)),O34),AK34) -> 0 | AM34: =AK34*($G$7/12) -> 106879.11 | AN34: =FORECAST(B34, $AM$2:$AY$2,$AM$1:$AY$1) -> 0.023297359 | AO34: =Q34+R34 -> 113333.33 | AP34: =Q34*B34 -> 1665532.7 | AQ34: =1/(1+(AN34+$CB$5)/12)^$B34 -> 0.93352293 | AR34: =T34+U34 -> 791943.39 | AS34: =T34*A34 -> 11290517 | AT34: =1/(1+(AN34+$BV$5)/12)^$B34 -> 0.93802421 | AU34: =W34+X34 -> 58333.333 | AV34: =W34*A34 -> 0 | AW34: =1/(1+(AN34+$BW$5)/12)^$B34 -> 0.94016639 | AX34: =IF(Y35>Y34,0,Z34+AA34) -> 0 | AY34: =A34*Z34 -> 0 | AZ34: =1/(1+(AN34+$BZ$5)/12)^$B34 -> 0.95541136 | BA34: =AC34+AD34 -> 83333.333 | BB34: =AC34*A34 -> 0 | BC34: =1/(1+(AN34+$CA$5)/12)^$B34 -> 0.94627032 | BD34: =AF34+AG34 -> 246142.92 | BE34: =AF34*A34 -> 2597948.3 | BF34: =1/(1+(AN34+$BU$5)/12)^$B34 -> 0.94233917 | BG34: =AI34+AJ34 -> 58125 | BH34: =AI34*A34 -> 0 | BI34: =1/(1+(AN34+$BX$5)/12)^$B34 -> 0.94923925 | BJ34: =IF(AK35>AK34,0,AL34+AM34) -> 0 | BK34: =A34*AL34 -> 0 | BL34: =1/(1+(AN34+$BY$5)/12)^$B34 -> 0.95260859 | BM34: =AO34+AR34+AU34+AX34+BA34+BD34+BG34+BJ34 -> 1351211.3 | BN34: =M34*B34 -> 8915051.4 | BO34: =1/(1+(AN34+$CC$5)/12)^$B34 -> 0.94528194
